Workbook

Sheet A to B
A1: Actual to Budget
A2: As of 31 August 2026
A3: Amounts in € (EUR)
D5: Month-to-Date (MTD) | H5: Year-to-Date (YTD) | L5: FY26 | N5: YTD A to B
D6: ACTUAL | E6: BUDGET | F6: △ | H6: ACTUAL | I6: BUDGET | J6: △ | L6: BUDGET | N6: %
B7: Airline | D7: =-SUMIFS(ACTUAL!$C:$C,ACTUAL!$A:$A,'A to B'!B7,ACTUAL!$B:$B,ACTUAL!$A$1) -> 395645.38 | E7: =SUMIFS(BUDGET!C:C,BUDGET!A:A,ACTUAL!$A$1)*VLOOKUP(B7,BUDGET!$J$3:$K$9,2,0) -> 377451.8 | F7: =+D7-E7 -> 18193.576 | H7: =-SUMIFS(ACTUAL!$C:$C,ACTUAL!$A:$A,'A to B'!B7,ACTUAL!$B:$B,"<="&ACTUAL!$A$1,ACTUAL!$B:$B,">="&ACTUAL!$A$2) -> 1957529 | I7: =SUMIFS(BUDGET!C:C,BUDGET!$A:$A,"<="&ACTUAL!$A$1,BUDGET!$A:$A,">="&ACTUAL!$A$2)*VLOOKUP(B7,BUDGET!$J$3:$K$9,2,0) -> 1830484.3 | J7: =+H7-I7 -> 127044.74 | L7: =SUM(BUDGET!$C$55:$C$66)*VLOOKUP(B7,BUDGET!$J$3:$K$9,2,0) -> 4672155.1 | N7: =H7/I7-1 -> 0.069404986
B8: Forwarder | D8: =-SUMIFS(ACTUAL!$C:$C,ACTUAL!$A:$A,'A to B'!B8,ACTUAL!$B:$B,ACTUAL!$A$1) -> 119115.56 | E8: =SUMIFS(BUDGET!C:C,BUDGET!A:A,ACTUAL!$A$1)*VLOOKUP(B8,BUDGET!$J$3:$K$9,2,0) -> 125817.27 | F8: =+D8-E8 -> -6701.708 | H8: =-SUMIFS(ACTUAL!$C:$C,ACTUAL!$A:$A,'A to B'!B8,ACTUAL!$B:$B,"<="&ACTUAL!$A$1,ACTUAL!$B:$B,">="&ACTUAL!$A$2) -> 642772.08 | I8: =SUMIFS(BUDGET!C:C,BUDGET!$A:$A,"<="&ACTUAL!$A$1,BUDGET!$A:$A,">="&ACTUAL!$A$2)*VLOOKUP(B8,BUDGET!$J$3:$K$9,2,0) -> 610161.42 | J8: =+H8-I8 -> 32610.658 | L8: =SUM(BUDGET!$C$55:$C$66)*VLOOKUP(B8,BUDGET!$J$3:$K$9,2,0) -> 1557385 | N8: =H8/I8-1 -> 0.053445953
B9: GSA | D9: =-SUMIFS(ACTUAL!$C:$C,ACTUAL!$A:$A,'A to B'!B9,ACTUAL!$B:$B,ACTUAL!$A$1) -> 57691.48 | E9: =SUMIFS(BUDGET!C:C,BUDGET!A:A,ACTUAL!$A$1)*VLOOKUP(B9,BUDGET!$J$3:$K$9,2,0) -> 62908.634 | F9: =+D9-E9 -> -5217.154 | H9: =-SUMIFS(ACTUAL!$C:$C,ACTUAL!$A:$A,'A to B'!B9,ACTUAL!$B:$B,"<="&ACTUAL!$A$1,ACTUAL!$B:$B,">="&ACTUAL!$A$2) -> 254935.72 | I9: =SUMIFS(BUDGET!C:C,BUDGET!$A:$A,"<="&ACTUAL!$A$1,BUDGET!$A:$A,">="&ACTUAL!$A$2)*VLOOKUP(B9,BUDGET!$J$3:$K$9,2,0) -> 305080.71 | J9: =+H9-I9 -> -50144.991 | L9: =SUM(BUDGET!$C$55:$C$66)*VLOOKUP(B9,BUDGET!$J$3:$K$9,2,0) -> 778692.52 | N9: =H9/I9-1 -> -0.16436631
B10: Airport | D10: =-SUMIFS(ACTUAL!$C:$C,ACTUAL!$A:$A,'A to B'!B10,ACTUAL!$B:$B,ACTUAL!$A$1) -> 21081.99 | E10: =SUMIFS(BUDGET!C:C,BUDGET!A:A,ACTUAL!$A$1)*VLOOKUP(B10,BUDGET!$J$3:$K$9,2,0) -> 31454.317 | F10: =+D10-E10 -> -10372.327 | H10: =-SUMIFS(ACTUAL!$C:$C,ACTUAL!$A:$A,'A to B'!B10,ACTUAL!$B:$B,"<="&ACTUAL!$A$1,ACTUAL!$B:$B,">="&ACTUAL!$A$2) -> 113850.19 | I10: =SUMIFS(BUDGET!C:C,BUDGET!$A:$A,"<="&ACTUAL!$A$1,BUDGET!$A:$A,">="&ACTUAL!$A$2)*VLOOKUP(B10,BUDGET!$J$3:$K$9,2,0) -> 152540.36 | J10: =+H10-I10 -> -38690.165 | L10: =SUM(BUDGET!$C$55:$C$66)*VLOOKUP(B10,BUDGET!$J$3:$K$9,2,0) -> 389346.26 | N10: =H10/I10-1 -> -0.25363888
B11: Shipper | D11: =-SUMIFS(ACTUAL!$C:$C,ACTUAL!$A:$A,'A to B'!B11,ACTUAL!$B:$B,ACTUAL!$A$1) -> 35749.89 | E11: =SUMIFS(BUDGET!C:C,BUDGET!A:A,ACTUAL!$A$1)*VLOOKUP(B11,BUDGET!$J$3:$K$9,2,0) -> 25163.454 | F11: =+D11-E11 -> 10586.436 | H11: =-SUMIFS(ACTUAL!$C:$C,ACTUAL!$A:$A,'A to B'!B11,ACTUAL!$B:$B,"<="&ACTUAL!$A$1,ACTUAL!$B:$B,">="&ACTUAL!$A$2) -> 151144.81 | I11: =SUMIFS(BUDGET!C:C,BUDGET!$A:$A,"<="&ACTUAL!$A$1,BUDGET!$A:$A,">="&ACTUAL!$A$2)*VLOOKUP(B11,BUDGET!$J$3:$K$9,2,0) -> 122032.28 | J11: =+H11-I11 -> 29112.526 | L11: =SUM(BUDGET!$C$55:$C$66)*VLOOKUP(B11,BUDGET!$J$3:$K$9,2,0) -> 311477.01 | N11: =H11/I11-1 -> 0.23856413
B12: PY Adjustments | D12: =-SUMIFS(ACTUAL!$C:$C,ACTUAL!$A:$A,'A to B'!B12,ACTUAL!$B:$B,ACTUAL!$A$1) -> 0 | E12: =SUMIFS(BUDGET!C:C,BUDGET!A:A,ACTUAL!$A$1)*VLOOKUP(B12,BUDGET!$J$3:$K$9,2,0) -> 0 | F12: =+D12-E12 -> 0 | H12: =-SUMIFS(ACTUAL!$C:$C,ACTUAL!$A:$A,'A to B'!B12,ACTUAL!$B:$B,"<="&ACTUAL!$A$1,ACTUAL!$B:$B,">="&ACTUAL!$A$2) -> 40165.81 | I12: =SUMIFS(BUDGET!C:C,BUDGET!$A:$A,"<="&ACTUAL!$A$1,BUDGET!$A:$A,">="&ACTUAL!$A$2)*VLOOKUP(B12,BUDGET!$J$3:$K$9,2,0) -> 0 | J12: =+H12-I12 -> 40165.81 | L12: =SUM(BUDGET!$C$55:$C$66)*VLOOKUP(B12,BUDGET!$J$3:$K$9,2,0) -> 0 | N12: 0
B13: Other Revenue | D13: =-SUMIFS(ACTUAL!$C:$C,ACTUAL!$A:$A,'A to B'!B13,ACTUAL!$B:$B,ACTUAL!$A$1) -> 11508.93 | E13: =SUMIFS(BUDGET!C:C,BUDGET!A:A,ACTUAL!$A$1)*VLOOKUP(B13,BUDGET!$J$3:$K$9,2,0) -> 6290.8634 | F13: =+D13-E13 -> 5218.0666 | H13: =-SUMIFS(ACTUAL!$C:$C,ACTUAL!$A:$A,'A to B'!B13,ACTUAL!$B:$B,"<="&ACTUAL!$A$1,ACTUAL!$B:$B,">="&ACTUAL!$A$2) -> 56495.38 | I13: =SUMIFS(BUDGET!C:C,BUDGET!$A:$A,"<="&ACTUAL!$A$1,BUDGET!$A:$A,">="&ACTUAL!$A$2)*VLOOKUP(B13,BUDGET!$J$3:$K$9,2,0) -> 30508.071 | J13: =+H13-I13 -> 25987.309 | L13: =SUM(BUDGET!$C$55:$C$66)*VLOOKUP(B13,BUDGET!$J$3:$K$9,2,0) -> 77869.252 | N13: =H13/I13-1 -> 0.8518175
B14: Total Revenue | D14: =SUM(D7:D13) -> 640793.23 | E14: =SUM(E7:E13) -> 629086.34 | F14: =SUM(F7:F13) -> 11706.89 | H14: =SUM(H7:H13) -> 3216893 | I14: =SUM(I7:I13) -> 3050807.1 | J14: =H14-I14 -> 166085.88 | L14: =SUM(L7:L13) -> 7786925.2 | N14: =H14/I14-1 -> 0.054439981
B16: COGS | D16: =-SUMIFS(ACTUAL!$C:$C,ACTUAL!$A:$A,'A to B'!B16,ACTUAL!$B:$B,ACTUAL!$A$1) -> 6629.36 | E16: =-SUMIFS(BUDGET!D:D,BUDGET!A:A,ACTUAL!$A$1) -> -5440.9565 | F16: =+D16-E16 -> 12070.317 | H16: =-SUMIFS(ACTUAL!$C:$C,ACTUAL!$A:$A,'A to B'!B16,ACTUAL!$B:$B,"<="&ACTUAL!$A$1,ACTUAL!$B:$B,">="&ACTUAL!$A$2) -> -22483.7 | I16: =-SUMIFS(BUDGET!D:D,BUDGET!$A:$A,"<="&ACTUAL!$A$1,BUDGET!$A:$A,">="&ACTUAL!$A$2) -> -66930.29 | J16: =+H16-I16 -> 44446.59 | L16: =-SUM(BUDGET!$D$55:$D$66) -> -161578.81 | N16: =H16/I16-1 -> -0.66407287
B17: General | D17: =-SUMIFS(ACTUAL!$C:$C,ACTUAL!$A:$A,'A to B'!B17,ACTUAL!$B:$B,ACTUAL!$A$1) -> -105100.9 | E17: =-SUMIFS(BUDGET!E:E,BUDGET!A:A,ACTUAL!$A$1) -> -87258.189 | F17: =+D17-E17 -> -17842.711 | H17: =-SUMIFS(ACTUAL!$C:$C,ACTUAL!$A:$A,'A to B'!B17,ACTUAL!$B:$B,"<="&ACTUAL!$A$1,ACTUAL!$B:$B,">="&ACTUAL!$A$2) -> -549871.74 | I17: =-SUMIFS(BUDGET!E:E,BUDGET!$A:$A,"<="&ACTUAL!$A$1,BUDGET!$A:$A,">="&ACTUAL!$A$2) -> -499573.39 | J17: =+H17-I17 -> -50298.349 | L17: =-SUM(BUDGET!$E$55:$E$66) -> -1389455.7 | N17: =H17/I17-1 -> 0.1006826
B18: Personnel | D18: =-SUMIFS(ACTUAL!$C:$C,ACTUAL!$A:$A,'A to B'!B18,ACTUAL!$B:$B,ACTUAL!$A$1) -> -220384.75 | E18: =-SUMIFS(BUDGET!F:F,BUDGET!A:A,ACTUAL!$A$1) -> -278854.95 | F18: =+D18-E18 -> 58470.204 | H18: =-SUMIFS(ACTUAL!$C:$C,ACTUAL!$A:$A,'A to B'!B18,ACTUAL!$B:$B,"<="&ACTUAL!$A$1,ACTUAL!$B:$B,">="&ACTUAL!$A$2) -> -1082146.8 | I18: =-SUMIFS(BUDGET!F:F,BUDGET!$A:$A,"<="&ACTUAL!$A$1,BUDGET!$A:$A,">="&ACTUAL!$A$2) -> -1147557.3 | J18: =+H18-I18 -> 65410.511 | L18: =-SUM(BUDGET!$F$55:$F$66) -> -2731774.5 | N18: =H18/I18-1 -> -0.056999777
B19: Total Expenses | D19: =SUM(D16:D18) -> -318856.29 | E19: =SUM(E16:E18) -> -371554.1 | F19: =D19-E19 -> 52697.81 | H19: =SUM(H16:H18) -> -1654502.2 | I19: =SUM(I16:I18) -> -1714061 | J19: =H19-I19 -> 59558.752 | L19: =SUM(L16:L18) -> -4282809.1 | N19: =H19/I19-1 -> -0.03474716
B21: EBIT | D21: =D14+D19 -> 321936.94 | E21: =E14+E19 -> 257532.24 | F21: =D21-E21 -> 64404.7 | H21: =H14+H19 -> 1562390.8 | I21: =I14+I19 -> 1336746.1 | J21: =H21-I21 -> 225644.63 | L21: =L14+L19 -> 3504116.1 | N21: =H21/I21-1 -> 0.16880141
B22: EBIT % | D22: =D21/D14 -> 0.50240378 | E22: =E21/E14 -> 0.40937503 | F22: =D22-E22 -> 0.093028747 | H22: =H21/H14 -> 0.48568316 | I22: =I21/I14 -> 0.43816147 | J22: =H22-I22 -> 0.047521693 | L22: =L21/L14 -> 0.44999997
B24: Interest | D24: =-SUMIFS(ACTUAL!$C:$C,ACTUAL!$A:$A,'A to B'!B24,ACTUAL!$B:$B,ACTUAL!$A$1) -> 25518.75 | E24: =-SUMIFS(BUDGET!G:G,BUDGET!A:A,ACTUAL!$A$1) -> 18762 | F24: =+D24-E24 -> 6756.75 | H24: =-SUMIFS(ACTUAL!$C:$C,ACTUAL!$A:$A,'A to B'!B24,ACTUAL!$B:$B,"<="&ACTUAL!$A$1,ACTUAL!$B:$B,">="&ACTUAL!$A$2) -> 133026.21 | I24: =-SUMIFS(BUDGET!G:G,BUDGET!$A:$A,"<="&ACTUAL!$A$1,BUDGET!$A:$A,">="&ACTUAL!$A$2) -> 93810 | J24: =+H24-I24 -> 39216.21 | L24: =-SUM(BUDGET!$G$55:$G$66) -> 225144 | N24: =H24/I24-1 -> 0.4180387
B25: Taxes | D25: =-SUMIFS(ACTUAL!$C:$C,ACTUAL!$A:$A,'A to B'!B25,ACTUAL!$B:$B,ACTUAL!$A$1) -> -86093.95 | E25: =-SUMIFS(BUDGET!H:H,BUDGET!A:A,ACTUAL!$A$1) -> -81781.224 | F25: =+D25-E25 -> -4312.7258 | H25: =-SUMIFS(ACTUAL!$C:$C,ACTUAL!$A:$A,'A to B'!B25,ACTUAL!$B:$B,"<="&ACTUAL!$A$1,ACTUAL!$B:$B,">="&ACTUAL!$A$2) -> -411633.39 | I25: =-SUMIFS(BUDGET!H:H,BUDGET!$A:$A,"<="&ACTUAL!$A$1,BUDGET!$A:$A,">="&ACTUAL!$A$2) -> -396604.92 | J25: =+H25-I25 -> -15028.466 | L25: =-SUM(BUDGET!$H$55:$H$66) -> -1012300.3 | N25: =H25/I25-1 -> 0.037892787
B26: Net Income | D26: =SUM(D21,D24:D25) -> 261361.74 | E26: =SUM(E21,E24:E25) -> 194513.02 | F26: =SUM(F21,F24:F25) -> 66848.724 | H26: =SUM(H21,H24:H25) -> 1283783.6 | I26: =SUM(I21,I24:I25) -> 1033951.2 | J26: =SUM(J21,J24:J25) -> 249832.38 | L26: =SUM(L21,L24:L25) -> 2716959.8 | N26: =H26/I26-1 -> 0.24162879

Sheet A to PY
A1: Current Year Actual to Prior Year (PY)
A2: ='A to B'!A2 -> As of 31 August 2026
A3: Amounts in € (EUR)
D5: Month-to-Date (MTD) | H5: Year-to-Date (YTD) | L5: FY24 | N5: YTD A to PY
D6: ACTUAL | E6: PY | F6: △ | H6: ACTUAL | I6: PY | J6: △ | L6: PY | N6: %
B7: Airline | D7: ='A to B'!D7 -> 395645.38 | E7: =-SUMIFS(ACTUAL!$C:$C,ACTUAL!$A:$A,'A to PY'!B7,ACTUAL!$B:$B,EDATE(ACTUAL!$A$1,-12)) -> 355833.33 | F7: =D7-E7 -> 39812.05 | H7: ='A to B'!H7 -> 1957529 | I7: =-SUMIFS(ACTUAL!$C:$C,ACTUAL!$A:$A,'A to PY'!B7,ACTUAL!$B:$B,"<="&EDATE(ACTUAL!$A$1,-12),ACTUAL!$B:$B,">="&EDATE(ACTUAL!$A$2,-12)) -> 1709628.3 | J7: =H7-I7 -> 247900.72 | L7: =I7 -> 1709628.3 | N7: =H7/I7-1 -> 0.1450027
B8: Forwarder | D8: ='A to B'!D8 -> 119115.56 | E8: =-SUMIFS(ACTUAL!$C:$C,ACTUAL!$A:$A,'A to PY'!B8,ACTUAL!$B:$B,EDATE(ACTUAL!$A$1,-12)) -> 118759.92 | F8: =D8-E8 -> 355.64 | H8: ='A to B'!H8 -> 642772.08 | I8: =-SUMIFS(ACTUAL!$C:$C,ACTUAL!$A:$A,'A to PY'!B8,ACTUAL!$B:$B,"<="&EDATE(ACTUAL!$A$1,-12),ACTUAL!$B:$B,">="&EDATE(ACTUAL!$A$2,-12)) -> 581353.71 | J8: =H8-I8 -> 61418.37 | L8: =I8 -> 581353.71 | N8: =H8/I8-1 -> 0.10564716
B9: GSA | D9: ='A to B'!D9 -> 57691.48 | E9: =-SUMIFS(ACTUAL!$C:$C,ACTUAL!$A:$A,'A to PY'!B9,ACTUAL!$B:$B,EDATE(ACTUAL!$A$1,-12)) -> 33811.25 | F9: =D9-E9 -> 23880.23 | H9: ='A to B'!H9 -> 254935.72 | I9: =-SUMIFS(ACTUAL!$C:$C,ACTUAL!$A:$A,'A to PY'!B9,ACTUAL!$B:$B,"<="&EDATE(ACTUAL!$A$1,-12),ACTUAL!$B:$B,">="&EDATE(ACTUAL!$A$2,-12)) -> 176236.8 | J9: =H9-I9 -> 78698.92 | L9: =I9 -> 176236.8 | N9: =H9/I9-1 -> 0.44655214
B10: Airport | D10: ='A to B'!D10 -> 21081.99 | E10: =-SUMIFS(ACTUAL!$C:$C,ACTUAL!$A:$A,'A to PY'!B10,ACTUAL!$B:$B,EDATE(ACTUAL!$A$1,-12)) -> 18067.49 | F10: =D10-E10 -> 3014.5 | H10: ='A to B'!H10 -> 113850.19 | I10: =-SUMIFS(ACTUAL!$C:$C,ACTUAL!$A:$A,'A to PY'!B10,ACTUAL!$B:$B,"<="&EDATE(ACTUAL!$A$1,-12),ACTUAL!$B:$B,">="&EDATE(ACTUAL!$A$2,-12)) -> 75726.45 | J10: =H10-I10 -> 38123.74 | L10: =I10 -> 75726.45 | N10: =H10/I10-1 -> 0.50344021
B11: Shipper | D11: ='A to B'!D11 -> 35749.89 | E11: =-SUMIFS(ACTUAL!$C:$C,ACTUAL!$A:$A,'A to PY'!B11,ACTUAL!$B:$B,EDATE(ACTUAL!$A$1,-12)) -> 23790.9 | F11: =D11-E11 -> 11958.99 | H11: ='A to B'!H11 -> 151144.81 | I11: =-SUMIFS(ACTUAL!$C:$C,ACTUAL!$A:$A,'A to PY'!B11,ACTUAL!$B:$B,"<="&EDATE(ACTUAL!$A$1,-12),ACTUAL!$B:$B,">="&EDATE(ACTUAL!$A$2,-12)) -> 114411.27 | J11: =H11-I11 -> 36733.54 | L11: =I11 -> 114411.27 | N11: =H11/I11-1 -> 0.32106575
B12: PY Adjustments | D12: ='A to B'!D12 -> 0 | E12: =-SUMIFS(ACTUAL!$C:$C,ACTUAL!$A:$A,'A to PY'!B12,ACTUAL!$B:$B,EDATE(ACTUAL!$A$1,-12)) -> 0 | F12: =D12-E12 -> 0 | H12: ='A to B'!H12 -> 40165.81 | I12: =-SUMIFS(ACTUAL!$C:$C,ACTUAL!$A:$A,'A to PY'!B12,ACTUAL!$B:$B,"<="&EDATE(ACTUAL!$A$1,-12),ACTUAL!$B:$B,">="&EDATE(ACTUAL!$A$2,-12)) -> 0 | J12: =H12-I12 -> 40165.81 | L12: =I12 -> 0 | N12: 0
B13: Other Revenue | D13: ='A to B'!D13 -> 11508.93 | E13: =-SUMIFS(ACTUAL!$C:$C,ACTUAL!$A:$A,'A to PY'!B13,ACTUAL!$B:$B,EDATE(ACTUAL!$A$1,-12)) -> 13678.47 | F13: =D13-E13 -> -2169.54 | H13: ='A to B'!H13 -> 56495.38 | I13: =-SUMIFS(ACTUAL!$C:$C,ACTUAL!$A:$A,'A to PY'!B13,ACTUAL!$B:$B,"<="&EDATE(ACTUAL!$A$1,-12),ACTUAL!$B:$B,">="&EDATE(ACTUAL!$A$2,-12)) -> 55679.24 | J13: =H13-I13 -> 816.14 | L13: =I13 -> 55679.24 | N13: =H13/I13-1 -> 0.014657887
B14: Total Revenue | D14: =SUM(D7:D13) -> 640793.23 | E14: =SUM(E7:E13) -> 563941.36 | F14: =D14-E14 -> 76851.87 | H14: =SUM(H7:H13) -> 3216893 | I14: =SUM(I7:I13) -> 2713035.8 | J14: =H14-I14 -> 503857.24 | L14: =SUM(L7:L13) -> 2713035.8 | N14: =H14/I14-1 -> 0.18571714
B16: COGS | D16: ='A to B'!D16 -> 6629.36 | E16: =-SUMIFS(ACTUAL!$C:$C,ACTUAL!$A:$A,'A to PY'!B16,ACTUAL!$B:$B,EDATE(ACTUAL!$A$1,-12)) -> -2744.64 | F16: =D16-E16 -> 9374 | H16: ='A to B'!H16 -> -22483.7 | I16: =-SUMIFS(ACTUAL!$C:$C,ACTUAL!$A:$A,'A to PY'!B16,ACTUAL!$B:$B,"<="&EDATE(ACTUAL!$A$1,-12),ACTUAL!$B:$B,">="&EDATE(ACTUAL!$A$2,-12)) -> -7191.03 | J16: =H16-I16 -> -15292.67 | L16: =I16 -> -7191.03 | N16: =H16/I16-1 -> 2.1266314
B17: General | D17: ='A to B'!D17 -> -105100.9 | E17: =-SUMIFS(ACTUAL!$C:$C,ACTUAL!$A:$A,'A to PY'!B17,ACTUAL!$B:$B,EDATE(ACTUAL!$A$1,-12)) -> -60816.31 | F17: =D17-E17 -> -44284.59 | H17: ='A to B'!H17 -> -549871.74 | I17: =-SUMIFS(ACTUAL!$C:$C,ACTUAL!$A:$A,'A to PY'!B17,ACTUAL!$B:$B,"<="&EDATE(ACTUAL!$A$1,-12),ACTUAL!$B:$B,">="&EDATE(ACTUAL!$A$2,-12)) -> -410939.26 | J17: =H17-I17 -> -138932.48 | L17: =I17 -> -410939.26 | N17: =H17/I17-1 -> 0.3380852
B18: Personnel | D18: ='A to B'!D18 -> -220384.75 | E18: =-SUMIFS(ACTUAL!$C:$C,ACTUAL!$A:$A,'A to PY'!B18,ACTUAL!$B:$B,EDATE(ACTUAL!$A$1,-12)) -> -188085.27 | F18: =D18-E18 -> -32299.48 | H18: ='A to B'!H18 -> -1082146.8 | I18: =-SUMIFS(ACTUAL!$C:$C,ACTUAL!$A:$A,'A to PY'!B18,ACTUAL!$B:$B,"<="&EDATE(ACTUAL!$A$1,-12),ACTUAL!$B:$B,">="&EDATE(ACTUAL!$A$2,-12)) -> -1007071.8 | J18: =H18-I18 -> -75075.05 | L18: =I18 -> -1007071.8 | N18: =H18/I18-1 -> 0.074547866
B19: Total Expenses | D19: =SUM(D16:D18) -> -318856.29 | E19: =SUM(E16:E18) -> -251646.22 | F19: =D19-E19 -> -67210.07 | H19: =SUM(H16:H18) -> -1654502.2 | I19: =SUM(I16:I18) -> -1425202 | J19: =H19-I19 -> -229300.2 | L19: =SUM(L16:L18) -> -1425202 | N19: =H19/I19-1 -> 0.16088961
B21: EBIT | D21: =D14+D19 -> 321936.94 | E21: =E14+E19 -> 312295.14 | F21: =D21-E21 -> 9641.8 | H21: =H14+H19 -> 1562390.8 | I21: =I14+I19 -> 1287833.7 | J21: =H21-I21 -> 274557.04 | L21: =L14+L19 -> 1287833.7 | N21: =H21/I21-1 -> 0.21319293
B22: EBIT % | D22: =D21/D14 -> 0.50240378 | E22: =E21/E14 -> 0.55377236 | F22: =D22-E22 -> -0.051368585 | H22: =H21/H14 -> 0.48568316 | I22: =I21/I14 -> 0.47468365 | J22: =H22-I22 -> 0.01099951 | L22: =L21/L14 -> 0.47468365
B24: Interest | D24: ='A to B'!D24 -> 25518.75 | E24: =-SUMIFS(ACTUAL!$C:$C,ACTUAL!$A:$A,'A to PY'!B24,ACTUAL!$B:$B,EDATE(ACTUAL!$A$1,-12)) -> 15566.35 | F24: =D24-E24 -> 9952.4 | H24: ='A to B'!H24 -> 133026.21 | I24: =-SUMIFS(ACTUAL!$C:$C,ACTUAL!$A:$A,'A to PY'!B24,ACTUAL!$B:$B,"<="&EDATE(ACTUAL!$A$1,-12),ACTUAL!$B:$B,">="&EDATE(ACTUAL!$A$2,-12)) -> 75642.17 | J24: =H24-I24 -> 57384.04 | L24: =I24 -> 75642.17 | N24: =H24/I24-1 -> 0.75862498
B25: Taxes | D25: ='A to B'!D25 -> -86093.95 | E25: =-SUMIFS(ACTUAL!$C:$C,ACTUAL!$A:$A,'A to PY'!B25,ACTUAL!$B:$B,EDATE(ACTUAL!$A$1,-12)) -> -85833 | F25: =D25-E25 -> -260.95 | H25: ='A to B'!H25 -> -411633.39 | I25: =-SUMIFS(ACTUAL!$C:$C,ACTUAL!$A:$A,'A to PY'!B25,ACTUAL!$B:$B,"<="&EDATE(ACTUAL!$A$1,-12),ACTUAL!$B:$B,">="&EDATE(ACTUAL!$A$2,-12)) -> -341502 | J25: =H25-I25 -> -70131.39 | L25: =I25 -> -341502 | N25: =H25/I25-1 -> 0.20536158
B26: Net Income | D26: =D21+SUM(D24:D25) -> 261361.74 | E26: =E21+SUM(E24:E25) -> 242028.49 | F26: =D26-E26 -> 19333.25 | H26: =H21+SUM(H24:H25) -> 1283783.6 | I26: =I21+SUM(I24:I25) -> 1021973.9 | J26: =H26-I26 -> 261809.69 | L26: =L21+SUM(L24:L25) -> 1021973.9 | N26: =H26/I26-1 -> 0.25618041

Sheet ACTUAL
A1: 46235 | B1: Current Year End
A2: 46113 | B2: Current Year Start
A3: Review EBIT | B3: Period | C3: Actual (EUR)
A4: Airline | B4: 46235 | C4: -395645.38
A5: Airport | B5: 46235 | C5: -21081.99
A6: COGS | B6: 46235 | C6: -6629.36
A7: Forwarder | B7: 46235 | C7: -119115.56
A8: General | B8: 46235 | C8: 105100.9
A9: GSA | B9: 46235 | C9: -57691.48
A10: Interest | B10: 46235 | C10: -25518.75
A11: Other Revenue | B11: 46235 | C11: -11508.93
A12: Personnel | B12: 46235 | C12: 220384.75
A13: Shipper | B13: 46235 | C13: -35749.89
A14: Taxes | B14: 46235 | C14: 86093.95
A15: PY Adjustments | B15: 46235 | C15: 0
... A129: Taxes | B129: 45931 | C129: 107561.76
A130: Airline | B130: 45901 | C130: -390061.92 | L130: Airline
A131: Airport | B131: 45901 | C131: -21385.45
A132: COGS | B132: 45901 | C132: 2810.74
A133: Forwarder | B133: 45901 | C133: -136045.4
A134: General | B134: 45901 | C134: 113547.76
A135: GSA | B135: 45901 | C135: -34093.18
A136: Interest | B136: 45901 | C136: -36819.38
A137: Other Revenue | B137: 45901 | C137: -8574.2
A138: Personnel | B138: 45901 | C138: 208806.25
A139: Shipper | B139: 45901 | C139: -20614.21
A140: Taxes | B140: 45901 | C140: 78748.41
A141: Airline | B141: 45870 | C141: -355833.33
A142: Airport | B142: 45870 | C142: -18067.49
... A575: Taxes | B575: 44562 | C575: 26226

Sheet BUDGET
J2: FY 26/27 | K2: Based on past avg trend
A3: Period | B3: EBIT - Budget | C3: Revenue - Budget | D3: COGS - Budget | E3: General - Budget | F3: Personnel - Budget | G3: Interest - Budget | H3: Taxes - Budget | J3: Airline | K3: 0.6
A4: 44562 | J4: Forwarder | K4: 0.2
A5: 44593 | J5: GSA | K5: 0.1
A6: 44621 | J6: Airport | K6: 0.05
A7: 44652 | J7: Shipper | K7: 0.04
A8: 44682 | J8: PY Adjustments | K8: 0
A9: 44713 | J9: Other Revenue | K9: 0.01
A10: 44743
A11: 44774
A12: 44805
A13: 44835
A14: 44866
A15: 44896
A16: 44927
A17: 44958
A18: 44986
A19: 45017 | B19: 196350 | C19: 327250
A20: 45047 | B20: 200700 | C20: 334500
A21: 45078 | B21: 205050 | C21: 341750
A22: 45108 | B22: 209400 | C22: 349000
A23: 45139 | B23: 213750 | C23: 356250
A24: 45170 | B24: 218100 | C24: 363500
A25: 45200 | B25: 222450 | C25: 370750
A26: 45231 | B26: 226800 | C26: 378000
A27: 45261 | B27: 231150 | C27: 385250
A28: 45292 | B28: 235500 | C28: 392500
A29: 45323 | B29: 239850 | C29: 399750
A30: 45352 | B30: 244200 | C30: 407000
... A54: 46082 | B54: 196561.95 | C54: 589414.87
A55: 46113 | B55: 307804.86 | C55: 585098.47 | D55: 5146.2348 | E55: 85533.752 | F55: 187327.01 | G55: -18762 | H55: =+Table1[[#This Row],[Revenue - Budget]]*13% -> 76062.802
A56: 46143 | B56: 333267.01 | C56: 615915.91 | D56: 5178.8404 | E56: 97142.723 | F56: 180993.59 | G56: -18762 | H56: =+Table1[[#This Row],[Revenue - Budget]]*13% -> 80069.068
A57: 46174 | B57: 169810.04 | C57: 613339.08 | D57: 33470.843 | E57: 116103.73 | F57: 294814.99 | G57: -18762 | H57: =+Table1[[#This Row],[Revenue - Budget]]*13% -> 79734.08
A58: 46204 | B58: 270572.13 | C58: 607367.3 | D58: 17693.415 | E58: 113534.99 | F58: 205566.77 | G58: -18762 | H58: =+Table1[[#This Row],[Revenue - Budget]]*13% -> 78957.749
A59: 46235 | B59: =253561.240123729+1731 -> 255292.24 | C59: =625115.340224942+3971 -> 629086.34 | D59: 5440.9565 | E59: 87258.189 | F59: 278854.95 | G59: -18762 | H59: =+Table1[[#This Row],[Revenue - Budget]]*13% -> 81781.224
A60: 46266 | B60: 296722.47 | C60: 656951.28 | D60: 6210.4473 | E60: 122779.7 | F60: 231238.66 | G60: -18762 | H60: =+Table1[[#This Row],[Revenue - Budget]]*13% -> 85403.666
A61: 46296 | B61: 325530.58 | C61: 693207.97 | D61: 36468.592 | E61: 114301.8 | F61: 216907 | G61: -18762 | H61: =+Table1[[#This Row],[Revenue - Budget]]*13% -> 90117.037
A62: 46327 | B62: 323740.01 | C62: 681957.85 | D62: 5275.3727 | E62: 131276.48 | F62: 221665.99 | G62: -18762 | H62: =+Table1[[#This Row],[Revenue - Budget]]*13% -> 88654.52
A63: 46357 | B63: 325877.68 | C63: 702539.95 | D63: 5282.0849 | E63: 134764.84 | F63: 236615.35 | G63: -18762 | H63: =+Table1[[#This Row],[Revenue - Budget]]*13% -> 91330.193
A64: 46388 | B64: 274493.94 | C64: 665961.74 | D64: 20527.972 | E64: 144402.76 | F64: 226537.07 | G64: -18762 | H64: =+Table1[[#This Row],[Revenue - Budget]]*13% -> 86575.026
...
