Workbook

Sheet P&L WACD
A1: Company: 124667 - WorldACD Market Data B.V.
A3: Balance sheet / Profit and loss statement
A6: Rev distribution per FY | Q6: =Q19/SUM($Q$19:$AB$19) -> 0.074776031 | R6: =R19/SUM($Q$19:$AB$19) -> 0.083490441 | S6: =S19/SUM($Q$19:$AB$19) -> 0.075336585 | T6: =T19/SUM($Q$19:$AB$19) -> 0.07805418 | U6: =U19/SUM($Q$19:$AB$19) -> 0.081204745 | V6: =V19/SUM($Q$19:$AB$19) -> 0.080437813 | W6: =W19/SUM($Q$19:$AB$19) -> 0.08489432 | X6: =X19/SUM($Q$19:$AB$19) -> 0.08538783 | ... AB6: =AB19/SUM($Q$19:$AB$19) -> 0.092105148 | AC6: =AC19/SUM($AC$19:$AN$19) -> 0.074676379 | AD6: =AD19/SUM($AC$19:$AN$19) -> 0.081064474 | AE6: =AE19/SUM($AC$19:$AN$19) -> 0.079698561 | AF6: =AF19/SUM($AC$19:$AN$19) -> 0.082174781 | AG6: =AG19/SUM($AC$19:$AN$19) -> 0.080414804 | AH6: =AH19/SUM($AC$19:$AN$19) -> 0.081936249 | AI6: =AI19/SUM($AC$19:$AN$19) -> 0.084780069 | AJ6: =AJ19/SUM($AC$19:$AN$19) -> 0.086797608 | ... AN6: =AN19/SUM($AC$19:$AN$19) -> 0.087963471 | AO6: =AO19/SUM($AO$19:$AZ$19) -> 0.075923013 | AP6: =AP19/SUM($AO$19:$AZ$19) -> 0.07748022 | AQ6: =AQ19/SUM($AO$19:$AZ$19) -> 0.078177321 | AR6: =AR19/SUM($AO$19:$AZ$19) -> 0.073821908 | AS6: =AS19/SUM($AO$19:$AZ$19) -> 0.080140305 | AT6: =AT19/SUM($AO$19:$AZ$19) -> 0.086795626 | AU6: =AU19/SUM($AO$19:$AZ$19) -> 0.093264005 | AV6: =AV19/SUM($AO$19:$AZ$19) -> 0.088356974 | ... AZ6: =AZ19/SUM($AO$19:$AZ$19) -> 0.092860354
A7: Particulars | B7: 2022 | C7: 2022 | D7: 2022 | E7: 2022 | F7: 2022 | G7: 2022 | H7: 2022 | I7: 2022 | J7: 2022 | K7: 2022 | L7: 2022 | M7: 2022 | N7: 2023 | O7: 2023 | P7: 2023 | Q7: 2023 | R7: 2023 | S7: 2023 | T7: 2023 | U7: 2023 | V7: 2023 | W7: 2023 | X7: 2023 | Y7: 2023 | Z7: 2024 | AA7: 2024 | AB7: 2024 | AC7: 2024 | AD7: 2024 | AE7: 2024 | AF7: 2024 | AG7: 2024 | AH7: 2024 | AI7: 2024 | AJ7: 2024 | AK7: 2024 | AL7: 2025 | AM7: 2025 | AN7: 2025 | AO7: 2025 | AP7: 2025 | AQ7: 2025 | AR7: 2025 | AS7: 2025 | AT7: 2025 | AU7: 2025 | AV7: 2025 | AW7: 2025 | AX7: 2026 | AY7: 2026 | AZ7: 2026 | BA7: 2026 | BB7: 2026 | BC7: 2026 | BD7: 2026 | BE7: 2026 | BF7: 2026 | BG7: 2025 | BH7: 2024 | BI7: 2023 | BJ7: FY2027 | BK7: FY2026 | BL7: FY2025 | BM7: FY2024 | BN7: FY2023 | BO7: FY2022 | BP7: Remarks
B8: January | C8: Februari | D8: March | E8: April | F8: May | G8: June | H8: July | I8: August | J8: September | K8: October | L8: November | M8: December | N8: January | O8: February | P8: March | Q8: April | R8: May | S8: June | T8: July | U8: August | V8: September | W8: October | X8: November | Y8: December | Z8: January | AA8: February | AB8: March | AC8: April | AD8: May | AE8: June | AF8: July | AG8: August | AH8: September | AI8: October | AJ8: November | AK8: December | AL8: January | AM8: February | AN8: March | AO8: April | AP8: May | AQ8: June | AR8: Jul | AS8: Aug | AT8: Sep | AU8: OCT | AV8: NOV | AW8: DEC | AX8: JAN | AY8: FEB | AZ8: MAR | BA8: APR | BB8: MAY | BC8: JUN | BD8: JUL | BE8: AUG | BF8: Total | BG8: Total | BH8: Total | BI8: Total | BJ8: Total | BK8: Total | BL8: Total | BM8: Total | BN8: Total | BO8: Total
A9: Profit and loss statement
A10: Gross margin
A11: Turnover
A12: 8400 - Turnover Airline | B12: -212427.24 | C12: -209910.73 | D12: -237563.67 | E12: -246794.29 | F12: -252583.71 | G12: -253028.07 | H12: -267357.32 | I12: -269824.48 | J12: -264391.88 | K12: -272661.31 | L12: -269216.39 | M12: -276889.25 | N12: -277258.01 | O12: -248239.08 | P12: -269843.96 | Q12: -271187.49 | R12: -284521.22 | S12: -281341.13 | T12: -294459.8 | U12: -304733.9 | V12: -297410.76 | W12: -305591.18 | X12: -300657.98 | Y12: -310981.73 | Z12: -307101.27 | AA12: -290242.86 | AB12: -313453.27 | AC12: -320579.06 | AD12: -329099.65 | AE12: -322160.9 | AF12: -341088.88 | AG12: -338087.72 | AH12: -337908.82 | AI12: -354813.3 | AJ12: -338698.12 | AK12: -341338.41 | AL12: -343853.07 | AM12: -310960.83 | AN12: -327130.77 | AO12: -333743.47 | AP12: -347838.97 | AQ12: -341992.87 | AR12: -330219.64 | AS12: -355833.33 | AT12: -390061.92 | AU12: -415418.59 | AV12: -390237.42 | AW12: -393057.44 | AX12: -338776.69 | AY12: -372164.38 | AZ12: -427667.19 | BA12: -383050.36 | BB12: -389957.34 | BC12: -400237.74 | BD12: -388638.18 | BE12: -395645.38 | BF12: =SUM(AX12:BE12) -> -3096137.3 | BG12: =SUM(AL12:AW12) -> -4280348.3 | BH12: =SUM(Z12:AK12) -> -3934572.3 | BI12: =SUM(N12:Y12) -> -3446226.2 | BJ12: =SUM(BA12:BE12) -> -1957529 | BK12: =SUM(AO12:AZ12) -> -4437011.9 | BL12: =SUM(AC12:AN12) -> -4005719.5 | BM12: =SUM(Q12:AB12) -> -3561682.6 | BN12: =SUM(E12:P12) -> -3168087.8 | BO12: =SUM(B12:D12) -> -659901.64
A13: 8401 - Turnover Airport | B13: -1250 | C13: -1250 | D13: -1250 | E13: -1250 | F13: -1250 | G13: -1250 | H13: -1250 | I13: -1250 | J13: -1479.45 | K13: -1528.77 | L13: -1479.45 | M13: -1528.77 | N13: -1528.77 | O13: -1380.82 | P13: -1528.77 | Q13: -1479.45 | R13: -1528.77 | S13: -1479.45 | T13: -1528.77 | U13: -1528.76 | V13: -1557.38 | W13: -1609.29 | X13: -1557.38 | Y13: -1609.29 | Z13: -1609.29 | AA13: -4476.77 | AB13: -4785.52 | AC13: -7085.7 | AD13: -7321.88 | AE13: -7085.7 | AF13: -10464.35 | AG13: -10464.34 | AH13: -10254.35 | AI13: -11406.74 | AJ13: -31778.52 | AK13: -15228.66 | AL13: -16727.73 | AM13: -16354.26 | AN13: -16736.43 | AO13: -13113.21 | AP13: -13550.32 | AQ13: -15900.52 | AR13: -15094.91 | AS13: -18067.49 | AT13: -21385.45 | AU13: -20809.38 | AV13: -19398.37 | AW13: -18855.91 | AX13: -19280.63 | AY13: -20464.36 | AZ13: -20177.1 | BA13: -21734.36 | BB13: -21027.36 | BC13: -25988.5 | BD13: -24017.98 | BE13: -21081.99 | BF13: =SUM(AX13:BE13) -> -173772.28 | BG13: =SUM(AL13:AW13) -> -205993.98 | BH13: =SUM(Z13:AK13) -> -121961.82 | BI13: =SUM(N13:Y13) -> -18316.9 | BJ13: =SUM(BA13:BE13) -> -113850.19 | BK13: =SUM(AO13:AZ13) -> -216097.65 | BL13: =SUM(AC13:AN13) -> -160908.66 | BM13: =SUM(Q13:AB13) -> -24750.12 | BN13: =SUM(E13:P13) -> -16704.8 | BO13: =SUM(B13:D13) -> -3750
A14: 8402 - Turnover Forwarder | B14: -43980.67 | C14: -39813.99 | D14: -43817.99 | E14: -39399.77 | F14: -45229.8 | G14: -48084.1 | H14: -45965.17 | I14: -47040.56 | J14: -45730.17 | K14: -50671.38 | L14: -49243.87 | M14: -47696.38 | N14: -49253.49 | O14: -48112.1 | P14: -53848.02 | Q14: -62216.51 | R14: -64716.2 | S14: -69475.77 | T14: -66092.95 | U14: -71573.98 | V14: -69478.96 | W14: -71975.54 | X14: -69653.77 | Y14: -75151.78 | Z14: -79783.88 | AA14: -74789.33 | AB14: -82348.7 | AC14: -76659.13 | AD14: -78034.9 | AE14: -84957.82 | AF14: -86055.81 | AG14: -86204.82 | AH14: -83423.99 | AI14: -94015.56 | AJ14: -94782.04 | AK14: -109973.56 | AL14: -121700.37 | AM14: -108473.19 | AN14: -121322.7 | AO14: -113455.67 | AP14: -112015.39 | AQ14: -125642.1 | AR14: -111480.63 | AS14: -118759.92 | AT14: -136045.4 | AU14: -126846.93 | AV14: -122927.72 | AW14: -131613.18 | AX14: -127494.89 | AY14: -95533.78 | AZ14: -121218.16 | BA14: -116152.23 | BB14: -130611.19 | BC14: -156785.28 | BD14: -120107.82 | BE14: -119115.56 | BF14: =SUM(AX14:BE14) -> -987018.91 | BG14: =SUM(AL14:AW14) -> -1450283.2 | BH14: =SUM(Z14:AK14) -> -1031029.5 | BI14: =SUM(N14:Y14) -> -771549.07 | BJ14: =SUM(BA14:BE14) -> -642772.08 | BK14: =SUM(AO14:AZ14) -> -1443033.8 | BL14: =SUM(AC14:AN14) -> -1145603.9 | BM14: =SUM(Q14:AB14) -> -857257.37 | BN14: =SUM(E14:P14) -> -570274.81 | BO14: =SUM(B14:D14) -> -127612.65
A15: 8403 - Turnover GSA | B15: -1178.08 | C15: -1178.08 | D15: -1305.48 | E15: -1301.37 | F15: -1714.98 | G15: -139.45 | H15: -1228.9 | I15: -1228.9 | J15: -1072.28 | K15: -1103.9 | L15: -1070.58 | M15: -1106.27 | N15: -5678.2 | O15: -3706.16 | P15: -4103.29 | Q15: -6196.56 | R15: -3878.29 | S15: -3937.55 | T15: -7008.05 | U15: -6232.23 | V15: -12845.95 | W15: -23390.47 | X15: -31187.83 | Y15: -32227.38 | Z15: -32795.63 | AA15: -31066.25 | AB15: -33463.22 | AC15: -38385.98 | AD15: -47118.62 | AE15: -45556.51 | AF15: -28681.02 | AG15: -28887.87 | AH15: -23817.74 | AI15: -29959.89 | AJ15: -32416.99 | AK15: -35923.6 | AL15: -37234.41 | AM15: -33562.09 | AN15: -36781.88 | AO15: -38365.62 | AP15: -35539.07 | AQ15: -34435.34 | AR15: -34085.52 | AS15: -33811.25 | AT15: -34093.18 | AU15: -38709.33 | AV15: -41724.9 | AW15: -54680.69 | AX15: -45399.56 | AY15: -43595.82 | AZ15: -45222.08 | BA15: -41778.39 | BB15: -44867.79 | BC15: -56485.84 | BD15: -54112.22 | BE15: -57691.48 | BF15: =SUM(AX15:BE15) -> -389153.18 | BG15: =SUM(AL15:AW15) -> -453023.28 | BH15: =SUM(Z15:AK15) -> -408073.32 | BI15: =SUM(N15:Y15) -> -140391.96 | BJ15: =SUM(BA15:BE15) -> -254935.72 | BK15: =SUM(AO15:AZ15) -> -479662.36 | BL15: =SUM(AC15:AN15) -> -418326.6 | BM15: =SUM(Q15:AB15) -> -224229.41 | BN15: =SUM(E15:P15) -> -23454.28 | BO15: =SUM(B15:D15) -> -3661.64
A16: 8404 - Turnover Shipper | J16: -805.48 | K16: -832.33 | L16: -805.48 | M16: -832.33 | N16: -832.33 | O16: -751.78 | P16: -832.33 | Q16: -1952.13 | R16: -2017.2 | S16: -1952.13 | T16: -2017.2 | U16: -2017.19 | V16: -1146.65 | W16: -1184.87 | X16: -1146.65 | Y16: -3861.06 | Z16: -3861.06 | AA16: -3611.95 | AB16: -3861.06 | AC16: -5331.96 | AD16: -5509.7 | AE16: -10186.29 | AF16: -10525.84 | AG16: -10525.84 | AH16: -12487.66 | AI16: -12903.92 | AJ16: -14131.5 | AK16: -11890.46 | AL16: -11401.75 | AM16: -10298.37 | AN16: -16709.97 | AO16: -21543.98 | AP16: -22262.09 | AQ16: -23023.43 | AR16: -23790.87 | AS16: -23790.9 | AT16: -20614.21 | AU16: -29881.85 | AV16: -33710.84 | AW16: -33536.49 | AX16: -28631.22 | AY16: -25860.44 | AZ16: -28705.26 | BA16: -27779.28 | BB16: -28705.24 | BC16: -27823.66 | BD16: -31086.74 | BE16: -35749.89 | BF16: =SUM(AX16:BE16) -> -234341.73 | BG16: =SUM(AL16:AW16) -> -270564.75 | BH16: =SUM(Z16:AK16) -> -104827.24 | BI16: =SUM(N16:Y16) -> -19711.52 | BJ16: =SUM(BA16:BE16) -> -151144.81 | BK16: =SUM(AO16:AZ16) -> -315351.58 | BL16: =SUM(AC16:AN16) -> -131903.26 | BM16: =SUM(Q16:AB16) -> -28629.15 | BN16: =SUM(E16:P16) -> -5692.06 | BO16: =SUM(B16:D16) -> 0
A17: 8405 - Turnover Other | AO17: 0 | AP17: -439.92 | AQ17: -425.73 | AR17: -4807.7 | AS17: -7136.47 | AT17: -8762.2 | AU17: -9054.28 | AV17: -8762.2 | AW17: -9054.28 | AX17: -10461.61 | AY17: -9449.2 | AZ17: -10461.61 | BA17: -11028.23 | BB17: -11408.63 | BC17: -11040.62 | BD17: -11508.97 | BE17: -11508.93 | BF17: =SUM(AX17:BE17) -> -86867.8 | BG17: =SUM(AL17:AW17) -> -48442.78 | BH17: =SUM(Z17:AK17) -> 0 | BJ17: =SUM(BA17:BE17) -> -56495.38 | BK17: =SUM(AO17:AZ17) -> -78815.2 | BL17: =SUM(AC17:AN17) -> 0
A18: 8500 - Turnover adjustments prior financial year | D18: 96.29 | E18: -0.01 | F18: -10000.01 | G18: -4596.27 | K18: -6875 | Q18: -12488.75 | R18: -40291.67 | W18: 123.29 | X18: -1770.83 | Y18: -3500 | AC18: 7708.2 | AD18: -10916.66 | AE18: 0 | AF18: -7732.5 | AG18: 0 | AH18: -15249.32 | AI18: 3188.78 | AJ18: 0 | AK18: -11095 | AL18: 0 | AM18: 0 | AN18: 0 | AO18: -14042.64 | AP18: -13576.78 | AQ18: -8708 | AR18: 0 | AS18: -6542 | AT18: 188 | AU18: -15571.5 | AV18: -5000 | AW18: -1882 | AX18: 0 | AY18: -1818.18 | AZ18: 0 | BA18: -16319.24 | BB18: -22895.35 | BC18: -951.22 | BD18: 0 | BE18: 0 | BF18: =SUM(AX18:BE18) -> -41983.99 | BG18: =SUM(AL18:AW18) -> -65134.92 | BH18: =SUM(Z18:AK18) -> -34096.5 | BI18: =SUM(N18:Y18) -> -57927.96 | BJ18: =SUM(BA18:BE18) -> -40165.81 | BK18: =SUM(AO18:AZ18) -> -66953.1 | BL18: =SUM(AC18:AN18) -> -34096.5 | BM18: =SUM(Q18:AB18) -> -57927.96 | BN18: =SUM(E18:P18) -> -21471.29 | BO18: =SUM(B18:D18) -> 96.29
A19: Total: Turnover | B19: -258835.99 | C19: -252152.8 | D19: -283840.85 | E19: -288745.44 | F19: -310778.5 | G19: -307097.89 | H19: -315801.39 | I19: -319343.94 | J19: -313479.26 | K19: -333672.69 | L19: -321815.77 | M19: -328053 | N19: -334550.8 | O19: -302189.94 | P19: -330156.37 | Q19: =SUM(Q12:Q18) -> -355520.89 | R19: =SUM(R12:R18) -> -396953.35 | S19: =SUM(S12:S18) -> -358186.03 | T19: =SUM(T12:T18) -> -371106.77 | U19: =SUM(U12:U18) -> -386086.06 | V19: =SUM(V12:V18) -> -382439.7 | W19: =SUM(W12:W18) -> -403628.06 | X19: =SUM(X12:X18) -> -405974.44 | ... BE19: =SUM(BE12:BE18) -> -640793.23 | BF19: =SUM(AX19:BE19) -> -5009275.1 | BG19: =SUM(AL19:AW19) -> -6773791.2 | BH19: =SUM(Z19:AK19) -> -5634560.7 | BI19: =SUM(N19:Y19) -> -4454123.7 | BJ19: =SUM(BA19:BE19) -> -3216893 | BK19: =SUM(AO19:AZ19) -> -7036925.6 | BL19: =SUM(AC19:AN19) -> -5896558.4 | BM19: =SUM(Q19:AB19) -> -4754476.6 | BN19: =SUM(E19:P19) -> -3805685 | BO19: =SUM(B19:D19) -> -794829.64
A20: Cost of sales | AO20: 0 | AP20: 0 | AQ20: 0 | AR20: 0 | AS20: 0 | AT20: 0 | AU20: 0 | AV20: 0 | AW20: 0 | AX20: 0 | AY20: 0
A21: 7300 - Licensing fees | B21: 2485.56 | C21: 2485.56 | D21: 2485.56 | E21: 2696.44 | F21: 2591.4 | G21: 2588.59 | H21: 1692.73 | I21: 1301.38 | J21: 2021.64 | K21: 4256.76 | L21: 4283.55 | M21: 4500.32 | N21: 3955.2 | O21: 5371.92 | P21: 5080.23 | Q21: 5047.62 | R21: 5654.3 | S21: 4938.7 | T21: 7019.09 | U21: 9676.97 | V21: 7319.91 | W21: 9276.64 | X21: 6103.61 | Y21: 5275.25 | Z21: 5617.87 | AA21: 7488.15 | AB21: 7142.85 | AC21: 7155.9 | AD21: 6655.11 | AE21: 36583.34 | AF21: 25780.1 | AG21: 5822.75 | AH21: 6136.45 | AI21: 55014.13 | AJ21: 1860.7 | AK21: 1929.01 | AL21: 1934.88 | AM21: 2029.5 | AN21: 1801.75 | AO21: 539.19 | AP21: 486.38 | AQ21: 805.44 | AR21: 2615.38 | AS21: 2744.64 | AT21: 2810.74 | AU21: 4828.72 | AV21: 6554.09 | AW21: 6772.57 | AX21: 32072.6 | AY21: 16499.66 | AZ21: 14980 | BA21: 14575.96 | BB21: 14685.17 | BC21: -361.53 | BD21: 213.46 | BE21: -6629.36 | BF21: =SUM(AX21:BE21) -> 86035.96 | BG21: =SUM(AL21:AW21) -> 33923.28 | BH21: =SUM(Z21:AK21) -> 167186.36 | BI21: =SUM(N21:Y21) -> 74719.44 | BJ21: =SUM(BA21:BE21) -> 22483.7 | BK21: =SUM(AO21:AZ21) -> 91709.41 | BL21: =SUM(AC21:AN21) -> 152703.62 | BM21: =SUM(Q21:AB21) -> 80560.96 | BN21: =SUM(E21:P21) -> 40340.16 | BO21: =SUM(B21:D21) -> 7456.68
A22: Total: Cost of sales | B22: 2485.56 | C22: 2485.56 | D22: 2485.56 | E22: 2696.44 | F22: 2591.4 | G22: 2588.59 | H22: 1692.73 | I22: 1301.38 | J22: 2021.64 | K22: 4256.76 | L22: 4283.55 | M22: 4500.32 | N22: 3955.2 | O22: 5371.92 | P22: 5080.23 | Q22: =SUM(Q21) -> 5047.62 | R22: =SUM(R21) -> 5654.3 | S22: =SUM(S21) -> 4938.7 | T22: =SUM(T21) -> 7019.09 | U22: =SUM(U21) -> 9676.97 | V22: =SUM(V21) -> 7319.91 | W22: =SUM(W21) -> 9276.64 | X22: =SUM(X21) -> 6103.61 | ... BE22: =SUM(BE21) -> -6629.36 | BF22: =SUM(AX22:BE22) -> 86035.96 | BG22: =SUM(AL22:AW22) -> 33923.28 | BH22: =SUM(Z22:AK22) -> 167186.36 | BI22: =SUM(N22:Y22) -> 74719.44 | BJ22: =SUM(BA22:BE22) -> 22483.7 | BK22: =SUM(AO22:AZ22) -> 91709.41 | BL22: =SUM(AC22:AN22) -> 152703.62 | BM22: =SUM(Q22:AB22) -> 80560.96 | BN22: =SUM(E22:P22) -> 40340.16 | BO22: =SUM(B22:D22) -> 7456.68 | BP22: COGS
A23: Total: Gross margin | B23: -256350.43 | C23: -249667.24 | D23: -281355.29 | E23: -286049 | F23: -308187.1 | G23: -304509.3 | H23: -314108.66 | I23: -318042.56 | J23: -311457.62 | K23: -329415.93 | L23: -317532.22 | M23: -323552.68 | N23: -330595.6 | O23: -296818.02 | P23: -325076.14 | Q23: =SUM(Q19+Q22) -> -350473.27 | R23: =SUM(R19+R22) -> -391299.05 | S23: =SUM(S19+S22) -> -353247.33 | T23: =SUM(T19+T22) -> -364087.68 | U23: =SUM(U19+U22) -> -376409.09 | V23: =SUM(V19+V22) -> -375119.79 | W23: =SUM(W19+W22) -> -394351.42 | X23: =SUM(X19+X22) -> -399870.83 | ... BE23: =SUM(BE19+BE22) -> -647422.59 | BF23: =SUM(AX23:BE23) -> -4923239.2 | BG23: =SUM(AL23:AW23) -> -6739868 | BH23: =SUM(Z23:AK23) -> -5467374.3 | BI23: =SUM(N23:Y23) -> -4379404.2 | BJ23: =SUM(BA23:BE23) -> -3194409.3 | BK23: =SUM(AO23:AZ23) -> -6945216.2 | BL23: =SUM(AC23:AN23) -> -5743854.8 | BM23: =SUM(Q23:AB23) -> -4673915.6 | BN23: =SUM(N23:Y23) -> -4379404.2 | BO23: =SUM(B23:D23) -> -787372.96
A24: Operating costs
A25: Personnel Expenses
A26: 4000 - Gross salary | B26: 28519.01 | C26: 28519.01 | D26: 28519.01 | E26: 28820.08 | F26: 28991.51 | G26: 28991.51 | H26: 32516.51 | I26: 32516.51 | J26: 38289.29 | K26: 39241.51 | L26: 39054.01 | M26: 39054.01 | N26: 43754.01 | O26: 46056.48 | P26: 44607.85 | Q26: 39759.99 | R26: 40177.99 | S26: 40627.99 | T26: 40909.99 | U26: 42866.51 | V26: 46303.53 | W26: 46330.74 | X26: 46330.74 | Y26: 49830.74 | Z26: 57004.59 | AA26: 57178.5 | AB26: 57178.5 | AC26: 61178.5 | AD26: 62127.5 | AE26: 70460.5 | AF26: 70460.5 | AG26: 69446.38 | AH26: 77238.38 | AI26: 78423.38 | AJ26: 74814.88 | AK26: 74814.88 | AL26: 82674.94 | AM26: 86782.18 | AN26: 81010.67 | AO26: 90056.79 | AP26: 86782.18 | AQ26: 89284.94 | AR26: 95960.18 | AS26: 96670.02 | AT26: 89043.18 | AU26: 102081.18 | AV26: 104414.66 | AW26: 104414.77 | AX26: 102341.06 | AY26: 103729.38 | AZ26: 109215.14 | BA26: 108764.98 | BB26: 108764.98 | BC26: 108764.98 | BD26: 104603.36 | BE26: 110330.54 | BF26: =SUM(AX26:BE26) -> 856514.42 | BG26: =SUM(AL26:AW26) -> 1109175.7 | BH26: =SUM(Z26:AK26) -> 810326.49 | BI26: =SUM(N26:Y26) -> 527556.56 | BJ26: =SUM(BA26:BE26) -> 541228.84 | BK26: =SUM(AO26:AZ26) -> 1173993.5 | BL26: =SUM(AC26:AN26) -> 889432.69 | BM26: =SUM(Q26:AB26) -> 564499.81 | BN26: =SUM(E26:P26) -> 441893.28 | BO26: =SUM(B26:D26) -> 85557.03
A27: 4002 - Bonus pay | D27: 0 | G27: 46739 | P27: 16000 | S27: 71644 | AC27: 0 | AD27: 0 | AE27: 0 | AF27: 0 | AG27: 97197 | AH27: 0 | AI27: 0 | AJ27: 2000 | AK27: 0 | AL27: 0 | AM27: 0 | AN27: 0 | AO27: 0 | AP27: 0 | AQ27: 159315 | AR27: 0 | AS27: 0 | AT27: 0 | AU27: 0 | AV27: 4758 | AW27: 0 | AX27: 0 | AY27: 0 | AZ27: 0 | BA27: 0 | BB27: 0 | BC27: 20810 | BD27: 15760 | BE27: 21115 | BF27: =SUM(AX27:BE27) -> 57685 | BG27: =SUM(AL27:AW27) -> 164073 | BH27: =SUM(Z27:AK27) -> 99197 | BI27: =SUM(N27:Y27) -> 87644 | BJ27: =SUM(BA27:BE27) -> 57685 | BK27: =SUM(AO27:AZ27) -> 164073 | BL27: =SUM(AC27:AN27) -> 99197 | BM27: =SUM(Q27:AB27) -> 71644 | BN27: =SUM(E27:P27) -> 62739 | BO27: =SUM(B27:D27) -> 0
A28: 4004 - Temporary staff | AC28: 0 | AD28: 0 | AE28: 3075 | AF28: 2025 | AG28: 0 | AH28: 1725 | AI28: 7050 | AJ28: 5775 | AK28: 2625 | AL28: 5250 | AM28: 0 | AN28: 0 | AO28: 3525 | AP28: 0 | AQ28: 3750 | AR28: 3112.5 | AS28: 3112.5 | AT28: 9525 | AU28: 8800 | AV28: 500 | AW28: 7950 | AX28: 7000 | AY28: -7000 | AZ28: 0 | BA28: 0 | BF28: =SUM(AX28:BE28) -> 0 | BG28: =SUM(AL28:AW28) -> 45525 | BH28: =SUM(Z28:AK28) -> 22275 | BI28: =SUM(N28:Y28) -> 0 | BJ28: =SUM(BA28:BE28) -> 0 | BK28: =SUM(AO28:AZ28) -> 40275 | BL28: =SUM(AC28:AN28) -> 27525
A29: 4006 - Pension premiums | B29: 2162.33 | C29: 2150.08 | D29: 2650.08 | E29: 2150.08 | F29: 2116.75 | G29: 2150.08 | H29: 2150.08 | I29: 2150.08 | J29: 2153.51 | K29: 2163.46 | L29: 4645.67 | M29: 3748.88 | N29: 3585.7 | O29: -500 | P29: 3167.88 | Q29: 6980.16 | R29: 4031.69 | S29: 3000 | T29: 3383.85 | U29: 3000 | V29: 3173.17 | W29: 3120.39 | X29: 6574.45 | Y29: 11299.45 | Z29: 6109.28 | AA29: 5610.89 | AB29: 7673.98 | AC29: 6528.67 | AD29: 7292.73 | AE29: 7207.26 | AF29: 8978 | AG29: 8018.49 | AH29: 17343.86 | AI29: 8421.93 | AJ29: 7397.77 | AK29: 7261.31 | AL29: 9416.01 | AM29: 6114.23 | AN29: 18925.47 | AO29: -1302.99 | AP29: -500 | AQ29: 18122.48 | AR29: -500 | AS29: 10989.73 | AT29: 22012.68 | AU29: 10756.34 | AV29: 18756.38 | AW29: 18750 | AX29: 8887.09 | AY29: 13117.15 | AZ29: 12316.2 | BA29: 12029.83 | BB29: 12029.83 | BC29: 12000 | BD29: 12377.19 | BE29: 12148.28 | BF29: =SUM(AX29:BE29) -> 94905.57 | BG29: =SUM(AL29:AW29) -> 131540.33 | BH29: =SUM(Z29:AK29) -> 97844.17 | BI29: =SUM(N29:Y29) -> 50816.74 | BJ29: =SUM(BA29:BE29) -> 60585.13 | BK29: =SUM(AO29:AZ29) -> 131405.06 | BL29: =SUM(AC29:AN29) -> 112905.73 | BM29: =SUM(Q29:AB29) -> 63957.31 | BN29: =SUM(E29:P29) -> 29682.17 | BO29: =SUM(B29:D29) -> 6962.49
A30: 4015 - Holiday allowance | B30: 2281.52 | C30: 2281.52 | D30: 2281.52 | E30: 2305.61 | F30: 2319.32 | G30: 2319.32 | H30: 2601.32 | I30: 2601.32 | J30: 3063.14 | K30: 3139.32 | L30: 3124.32 | M30: 3124.32 | N30: 3500.32 | O30: 3684.52 | P30: 3568.63 | Q30: 3180.8 | R30: 3214.24 | S30: 3250.24 | T30: 3272.8 | U30: 3429.32 | V30: 3704.28 | W30: 3706.46 | X30: 3706.46 | Y30: 3986.46 | Z30: 4400.37 | AA30: 4574.28 | AB30: 4574.28 | AC30: 4894.28 | AD30: 4970.2 | AE30: 5636.84 | AF30: 5636.84 | AG30: 5555.71 | AH30: 6179.07 | AI30: 2940.67 | AJ30: 5985.19 | AK30: 5985.19 | AL30: 6359.21 | AM30: 6942.58 | AN30: 6942.58 | AO30: 6942.58 | AP30: 6942.58 | AQ30: 7142.8 | AR30: 7676.82 | AS30: 7733.6 | AT30: 8547.05 | AU30: 8703.57 | AV30: 8890.25 | AW30: 8782.21 | AX30: 9249.03 | AY30: 9249.03 | AZ30: 9285.04 | BA30: 9249.03 | BB30: 9249.03 | BC30: 9249.03 | BD30: 9473.11 | BE30: 9384.47 | BF30: =SUM(AX30:BE30) -> 74387.77 | BG30: =SUM(AL30:AW30) -> 91605.83 | BH30: =SUM(Z30:AK30) -> 61332.92 | BI30: =SUM(N30:Y30) -> 42204.53 | BJ30: =SUM(BA30:BE30) -> 46604.67 | BK30: =SUM(AO30:AZ30) -> 99144.56 | BL30: =SUM(AC30:AN30) -> 68028.36 | BM30: =SUM(Q30:AB30) -> 44999.99 | BN30: =SUM(E30:P30) -> 35351.46 | BO30: =SUM(B30:D30) -> 6844.56
A31: 4016 - Work from home allowance | AC31: 0 | AD31: 0 | AE31: 0 | AF31: 0 | AG31: 0 | AH31: 0 | AI31: 0 | AJ31: 0 | AK31: 2800 | AL31: 2800 | AM31: 0 | AN31: 0 | AO31: 0 | AP31: 0 | AQ31: 0 | AR31: 0 | AS31: 0 | AT31: 0 | AU31: 0 | AV31: 0 | AW31: 0 | AX31: 0 | AY31: 0 | AZ31: 0 | BA31: 0 | BF31: =SUM(AX31:BE31) -> 0 | BG31: =SUM(AL31:AW31) -> 2800 | BH31: =SUM(Z31:AK31) -> 2800 | BI31: =SUM(N31:Y31) -> 0 | BJ31: =SUM(BA31:BE31) -> 0 | BK31: =SUM(AO31:AZ31) -> 0 | BL31: =SUM(AC31:AN31) -> 5600 | BM31: =SUM(Q31:AB31) -> 0 | BN31: =SUM(E31:P31) -> 0 | BO31: =SUM(B31:D31) -> 0
A32: 4017 - Employee Gifts | AM32: 0 | AN32: 0 | AO32: 0 | AP32: 0 | AQ32: 0 | AR32: 0 | AS32: 0 | AT32: 0 | AU32: 0 | AV32: 0 | AW32: 3049.52 | AX32: 0 | AY32: 0 | AZ32: 0 | BA32: 0 | BF32: =SUM(AX32:BE32) -> 0 | BG32: =SUM(AL32:AW32) -> 3049.52 | BH32: =SUM(Z32:AK32) -> 0 | BJ32: =SUM(BA32:BE32) -> 0 | BK32: =SUM(AO32:AZ32) -> 3049.52 | BL32: =SUM(AC32:AN32) -> 0
A33: 4041 - Social insurance premiums | B33: 5264.81 | C33: 5264.81 | D33: 5264.81 | E33: 5288.69 | F33: 4878.65 | G33: 7218.42 | H33: 5575.38 | I33: 5575.38 | J33: 6631.67 | K33: 6692.53 | L33: 6662.1 | M33: 7708.16 | N33: 8004.33 | O33: 8198.03 | P33: 8052.55 | Q33: 7345.49 | R33: 7191.58 | S33: 11591.22 | T33: 7594.72 | U33: 8012.44 | V33: 8499.19 | W33: 8496.48 | X33: 8496.48 | Y33: 11807.84 | Z33: 10356.82 | AA33: 10823.79 | AB33: 10823.79 | AC33: 9449.19 | AD33: 11124.54 | AE33: 12406.66 | AF33: 10572.09 | AG33: 19763.04 | AH33: 13564.39 | AI33: 13818.92 | AJ33: 13738.45 | AK33: 18827.09 | AL33: 13242.98 | AM33: 15680.76 | AN33: 15680.76 | AO33: 15467.81 | AP33: 15467.81 | AQ33: 28873.8 | AR33: 18031.72 | AS33: 17780.98 | AT33: 18745.18 | AU33: 19170.91 | AV33: 19548.75 | AW33: 26345.73 | AX33: 19665.7 | AY33: 19216.15 | AZ33: 19257.03 | BA33: 19016.05 | BB33: 19016.05 | BC33: 19016.05 | BD33: 38953.96 | BE33: 19562.45 | BF33: =SUM(AX33:BE33) -> 173703.44 | BG33: =SUM(AL33:AW33) -> 224037.19 | BH33: =SUM(Z33:AK33) -> 155268.77 | BI33: =SUM(N33:Y33) -> 103290.35 | BJ33: =SUM(BA33:BE33) -> 115564.56 | BK33: =SUM(AO33:AZ33) -> 237571.57 | BL33: =SUM(AC33:AN33) -> 167868.87 | BM33: =SUM(Q33:AB33) -> 111039.84 | BN33: =SUM(E33:P33) -> 80485.89 | BO33: =SUM(B33:D33) -> 15794.43
A34: 4050 - Study and training expenses | O34: 5000 | S34: 10500 | T34: 1210 | AC34: 0 | AD34: 0 | AE34: 0 | AF34: 0 | AG34: 0 | AH34: 0 | AI34: 0 | AJ34: 0 | AK34: 0 | AL34: 0 | AM34: 0 | AN34: 0 | AO34: 0 | AP34: 0 | AQ34: 0 | AR34: 3652.07 | AS34: 4079.47 | AT34: 20432.9 | AU34: -23888 | AV34: 0 | AW34: 3219.99 | AX34: 1914.89 | AY34: 243.2 | AZ34: 11540.47 | BA34: 753.08 | BB34: 5813.69 | BC34: 12148.38 | BD34: 1778.97 | BE34: 2653.98 | BF34: =SUM(AX34:BE34) -> 36846.66 | BG34: =SUM(AL34:AW34) -> 7496.43 | BI34: =SUM(N34:Y34) -> 16710 | BJ34: =SUM(BA34:BE34) -> 23148.1 | BK34: =SUM(AO34:AZ34) -> 21194.99 | BL34: =SUM(AC34:AN34) -> 0 | BM34: =SUM(Q34:AB34) -> 11710 | BN34: =SUM(E34:P34) -> 5000 | BO34: =SUM(B34:D34) -> 0
A35: 4060 - Consumptions personnel discretionary scope (vrije ruimte) | AC35: 0 | AD35: 302.17 | AE35: 157.07 | AF35: 1262.32 | AG35: 391.83 | AH35: 501.2 | AI35: 340.1 | AJ35: 639.85 | AK35: 523.19 | AL35: 2735.37 | AM35: 618.73 | AN35: 614.78 | AO35: 772.28 | AP35: 667.3 | AQ35: 345.21 | AR35: 680.62 | AS35: 5851.72 | AT35: 1037.94 | AU35: 1304.46 | AV35: 707.44 | AW35: 5982.46 | AX35: 588.73 | AY35: 628.25 | AZ35: 860.38 | BA35: 418.08 | BB35: 735.83 | BC35: 201.59 | BD35: 300.44 | BE35: 496.11 | BF35: =SUM(AX35:BE35) -> 4229.41 | BG35: =SUM(AL35:AW35) -> 21318.31 | BH35: =SUM(Z35:AK35) -> 4117.73 | BJ35: =SUM(BA35:BE35) -> 2152.05 | BK35: =SUM(AO35:AZ35) -> 19426.79 | BL35: =SUM(AC35:AN35) -> 8086.61
A36: 4081 - Social insurance premiums holiday allowance | B36: 456.3 | C36: 456.3 | D36: 456.3 | E36: 461.12 | F36: 461.12 | G36: 461.12 | H36: 461.12 | I36: 461.12 | J36: 461.12 | K36: 461.12 | L36: 461.12 | M36: 461.12 | N36: 461.12 | O36: 461.12 | P36: 461.12 | Q36: 461.12 | R36: 461.12 | S36: 461.12 | T36: 461.12 | U36: 461.12 | V36: 461.12 | W36: 461.12 | X36: 461.12 | Y36: 461.12 | Z36: 461.12 | AA36: 461.12 | AB36: -9264.86 | AC36: 978.86 | AD36: 994.04 | AE36: 1127.37 | AF36: 1127.37 | AG36: 1111.14 | AH36: 1235.82 | AI36: 1254.78 | AJ36: 1197.04 | AK36: 1197.04 | AL36: 1255.14 | AM36: 1456.18 | AN36: 1388.52 | AO36: 1388.51 | AP36: 1388.51 | AQ36: 1428 | AR36: 1535.36 | AS36: 1546.72 | AT36: 1709.41 | AU36: 1709.41 | AV36: 1778.05 | AW36: 1778.05 | AX36: 1849.81 | AY36: 1849.81 | AZ36: 1849.81 | BA36: 1849.81 | BB36: 1849.81 | BC36: 1849.81 | BD36: 1876.89 | BE36: 1876.89 | BF36: =SUM(AX36:BE36) -> 14852.64 | BG36: =SUM(AL36:AW36) -> 18361.86 | BH36: =SUM(Z36:AK36) -> 1880.84 | BI36: =SUM(N36:Y36) -> 5533.44 | BJ36: =SUM(BA36:BE36) -> 9303.21 | BK36: =SUM(AO36:AZ36) -> 19811.45 | BL36: =SUM(AC36:AN36) -> 14323.3 | BM36: =SUM(Q36:AB36) -> -4192.54 | BN36: =SUM(E36:P36) -> 5533.44 | BO36: =SUM(B36:D36) -> 1368.9
A37: 4082 - Management Fee Shanwick B.V. | D37: 0 | F37: 31041.33 | G37: 31041.33 | H37: 31041.33 | I37: 31041.33 | J37: 31041.33 | K37: 31041.33 | L37: 31041.33 | M37: 31041.33 | N37: 31041.33 | O37: 31041.33 | P37: 31041.33 | Q37: 31041.33 | R37: 31041.33 | S37: 31041.33 | T37: 31041.33 | U37: 31041.33 | V37: 31041.33 | W37: 31041.33 | X37: 31041.33 | Y37: 31041.33 | Z37: 31041.33 | AA37: 31041.33 | AB37: 31041.33 | AC37: 31041.33 | AD37: 31041.33 | AE37: 31041.33 | AF37: 31041.33 | AG37: 31041.33 | AH37: 31041.33 | AI37: 31041.33 | AJ37: 31041.33 | AK37: 31041.33 | AL37: 31041.33 | AM37: 31041.33 | AN37: 31041.33 | AO37: 31041.33 | AP37: 33009.33 | AQ37: 31533.33 | AR37: 31533.33 | AS37: 31533.33 | AT37: 31533.33 | AU37: 31533.33 | AV37: 31533.33 | AW37: 31533.33 | AX37: 31533.33 | AY37: 31533.33 | AZ37: 31533.33 | BA37: 37731 | BB37: 37731 | BC37: 37731 | BD37: 37731 | BE37: 37731 | BF37: =SUM(AX37:BE37) -> 283254.99 | BG37: =SUM(AL37:AW37) -> 377907.96 | BH37: =SUM(Z37:AK37) -> 372495.96 | BI37: =SUM(N37:Y37) -> 372495.96 | BJ37: =SUM(BA37:BE37) -> 188655 | BK37: =SUM(AO37:AZ37) -> 379383.96 | BL37: =SUM(AC37:AN37) -> 372495.96 | BM37: =SUM(Q37:AB37) -> 372495.96 | BN37: =SUM(E37:P37) -> 341454.63 | BO37: =SUM(B37:D37) -> 0
A38: 4085 - Holiday leave | B38: 2000.98 | C38: 2000.98 | D38: 2000.99 | F38: 4001.97 | G38: 2001.98 | H38: 2001.98 | I38: 2001.98 | J38: 2001.98 | K38: 2001.98 | L38: 2001.98 | M38: 2001.98 | N38: 2001.98 | O38: 2001.98 | P38: 2001.98 | Q38: 2001.98 | R38: 2001.98 | S38: 2001.98 | T38: 2001.98 | U38: 2001.98 | V38: 2001.98 | W38: 2001.98 | X38: 2001.98 | Y38: 2001.98 | Z38: 2001.98 | AA38: 2001.98 | AB38: 2001.98 | AC38: 2001.98 | AD38: 2001.98 | AE38: 2001.98 | AF38: 2001.98 | AG38: 2001.98 | AH38: 2001.98 | AI38: 2001.98 | AJ38: 2001.98 | AK38: 2001.98 | AL38: 2001.98 | AM38: 2001.98 | AN38: 2001.98 | AO38: 2001.98 | AP38: 2001.98 | AQ38: 2001.98 | AR38: 2001.98 | AS38: 2001.98 | AT38: 2001.98 | AU38: 2001.98 | AV38: 2001.98 | AW38: 2001.98 | AX38: 2001.98 | AY38: 2001.98 | AZ38: 2001.98 | BA38: 2001.98 | BB38: 2001.98 | BC38: 2001.98 | BD38: 2001.98 | BE38: 2001.98 | BF38: =SUM(AX38:BE38) -> 16015.84 | BG38: =SUM(AL38:AW38) -> 24023.76 | BH38: =SUM(Z38:AK38) -> 24023.76 | BI38: =SUM(N38:Y38) -> 24023.76 | BJ38: =SUM(BA38:BE38) -> 10009.9 | BK38: =SUM(AO38:AZ38) -> 24023.76 | BL38: =SUM(AC38:AN38) -> 24023.76 | BM38: =SUM(Q38:AB38) -> 24023.76 | BN38: =SUM(E38:P38) -> 24021.77 | BO38: =SUM(B38:D38) -> 6002.95
A39: 4086 - Management Fee Decision Company B.V. | B39: 14370 | C39: 14508 | D39: 14508 | E39: 14508 | AC39: 0 | AD39: 0 | AE39: 0 | AF39: 0 | AG39: 0 | AH39: 0 | AI39: 0 | AJ39: 0 | AK39: 0 | AL39: 0 | AM39: 0 | AN39: 0 | AO39: 0 | AP39: 0 | AQ39: 0 | AR39: 0 | AS39: 0 | AT39: 0 | AU39: 0 | AV39: 0 | AW39: 0 | AX39: 0 | AY39: 0 | AZ39: 0 | BA39: 0 | BB39: 0 | BC39: 0 | BD39: 0 | BE39: 0 | BF39: =SUM(AX39:BE39) -> 0 | BG39: =SUM(AL39:AW39) -> 0 | BI39: =SUM(N39:Y39) -> 0 | BJ39: =SUM(BA39:BE39) -> 0 | BK39: =SUM(AO39:AZ39) -> 0 | BL39: =SUM(AC39:AN39) -> 0 | BM39: =SUM(Q39:AB39) -> 0 | BN39: =SUM(E39:P39) -> 14508 | BO39: =SUM(B39:D39) -> 43386
A40: 4087 - Management Fee Ubi Concordia B.V. | B40: 15990 | C40: 16533.33 | D40: 16533.33 | E40: 16533.33 | AC40: 0 | AD40: 0 | AE40: 0 | AF40: 0 | AG40: 0 | AH40: 0 | AI40: 0 | AJ40: 0 | AK40: 0 | AL40: 0 | AM40: 0 | AN40: 0 | AO40: 0 | AP40: 0 | AQ40: 0 | AR40: 0 | AS40: 0 | AT40: 0 | AU40: 0 | AV40: 0 | AW40: 0 | AX40: 0 | AY40: 0 | AZ40: 0 | BA40: 0 | BF40: =SUM(AX40:BE40) -> 0 | BG40: =SUM(AL40:AW40) -> 0 | BI40: =SUM(N40:Y40) -> 0 | BJ40: =SUM(BA40:BE40) -> 0 | BK40: =SUM(AO40:AZ40) -> 0 | BL40: =SUM(AC40:AN40) -> 0 | BM40: =SUM(Q40:AB40) -> 0 | BN40: =SUM(E40:P40) -> 16533.33 | BO40: =SUM(B40:D40) -> 49056.66
A41: 4090 - Other personnel exp. discretionary scope (vrije ruimte) | L41: 1454.5 | M41: 2132.54 | Z41: 1542.17 | AC41: 0 | AD41: 0 | AE41: 0 | AF41: 0 | AG41: 0 | AH41: 0 | AI41: 0 | AJ41: 0 | AK41: 0 | AL41: 0 | AM41: 0 | AN41: 0 | AO41: 0 | AP41: 0 | AQ41: 0 | AR41: 0 | AS41: 0 | AT41: 0 | AU41: 0 | AV41: 0 | AW41: 0 | AX41: 0 | AY41: 0 | AZ41: 0 | BA41: 0 | BF41: =SUM(AX41:BE41) -> 0 | BG41: =SUM(AL41:AW41) -> 0 | BI41: =SUM(N41:Y41) -> 0 | BJ41: =SUM(BA41:BE41) -> 0 | BK41: =SUM(AO41:AZ41) -> 0 | BL41: =SUM(AC41:AN41) -> 0 | BM41: =SUM(Q41:AB41) -> 1542.17 | BN41: =SUM(E41:P41) -> 3587.04 | BO41: =SUM(B41:D41) -> 0
A42: 4092 - Travel and subsistence expenses | C42: 27 | D42: 0 | E42: 523.37 | F42: 34 | G42: 382.4 | H42: 1065.03 | I42: 3493.08 | J42: 2025.8 | K42: 5713.65 | L42: 12153.25 | M42: 5858.36 | N42: 2807.95 | O42: 696.69 | P42: 5059.07 | Q42: 2551.19 | R42: 12228.2 | S42: 17070.91 | T42: 6941.82 | U42: -8116.77 | V42: -22.24 | W42: 1535.56 | X42: 3820.51 | Y42: 2316.33 | Z42: 1318.77 | AA42: 6349.18 | AB42: 3168.19 | AC42: 6317.26 | AD42: 757.61 | AE42: 7921.72 | AF42: 14264.9 | AG42: 4173.53 | AH42: 1548.73 | AI42: 12924.98 | AJ42: 5397.8 | AK42: 3826.67 | AL42: 2952.7 | AM42: 4543.71 | AN42: 5783.78 | AO42: 3030.98 | AP42: 11007.06 | AQ42: 1484.67 | AR42: 1389.41 | AS42: 6547.01 | AT42: 3986.18 | AU42: 8304.17 | AV42: 1889.71 | AW42: 4187.6 | AX42: 6757.46 | AY42: 5232.55 | AZ42: 3108.28 | BA42: 2586.97 | BB42: 6116.7 | BC42: 11549.1 | BD42: 2561.66 | BE42: 2751.29 | BF42: =SUM(AX42:BE42) -> 40664.01 | BG42: =SUM(AL42:AW42) -> 55106.98 | BH42: 68187.63 | BI42: =SUM(N42:Y42) -> 46889.22 | BJ42: =SUM(BA42:BE42) -> 25565.72 | BK42: =SUM(AO42:AZ42) -> 56925.08 | BL42: =SUM(AC42:AN42) -> 70413.39 | BM42: =SUM(Q42:AB42) -> 49161.65 | BN42: =SUM(E42:P42) -> 39812.65 | BO42: =SUM(B42:D42) -> 27
A43: 4093 - Recruitment expenses | N43: 16125 | W43: 1035 | X43: 1099.5 | Y43: 3090 | Z43: 344.85 | AA43: 16657.5 | AB43: 2160 | AC43: 14619 | AD43: 2490 | AE43: 0 | AF43: 0 | AG43: 0 | AH43: 0 | AI43: 0 | AJ43: 0 | AK43: 0 | AL43: 0 | AM43: 0 | AN43: 0 | AO43: 0 | AP43: 0 | AQ43: 0 | AR43: 0 | AS43: 0 | AT43: 0 | AU43: 0 | AV43: 0 | AW43: 0 | AX43: 0 | AY43: 0 | AZ43: 0 | BA43: 0 | BF43: =SUM(AX43:BE43) -> 0 | BG43: =SUM(AL43:AW43) -> 0 | BH43: 36271.35 | BI43: =SUM(N43:Y43) -> 21349.5 | BJ43: =SUM(BA43:BE43) -> 0 | BK43: =SUM(AO43:AZ43) -> 0 | BL43: =SUM(AC43:AN43) -> 17109 | BM43: =SUM(Q43:AB43) -> 24386.85 | BN43: =SUM(E43:P43) -> 16125 | BO43: =SUM(B43:D43) -> 0
...

Sheet Budget - Overview
A3: 1 | B3: Revenue | D3: Apr | E3: May | F3: Jun | G3: Jul | H3: Aug | I3: Sept | J3: Oct | K3: Nov | L3: Dec | M3: Jan | N3: Feb | O3: Mar | P3: Total | T3: Actual | U3: Actual | V3: Actual | W3: Actual | X3: Budget
B4: Actual | C4: FY 24/25 | D4: ='P&L WACD'!AC6 -> 0.074676379 | E4: ='P&L WACD'!AD6 -> 0.081064474 | F4: ='P&L WACD'!AE6 -> 0.079698561 | G4: ='P&L WACD'!AF6 -> 0.082174781 | H4: ='P&L WACD'!AG6 -> 0.080414804 | I4: ='P&L WACD'!AH6 -> 0.081936249 | J4: ='P&L WACD'!AI6 -> 0.084780069 | K4: ='P&L WACD'!AJ6 -> 0.086797608 | ... O4: ='P&L WACD'!AN6 -> 0.087963471 | P4: =SUM(D4:O4) -> 1 | T4: FY 22/23 | U4: FY 23/24 | V4: FY 24/25 | W4: FY25/26 | X4: FY26/27
B5: Actual | C5: FY 25/26 | D5: ='P&L WACD'!AO6 -> 0.075923013 | E5: ='P&L WACD'!AP6 -> 0.07748022 | F5: ='P&L WACD'!AQ6 -> 0.078177321 | G5: ='P&L WACD'!AR6 -> 0.073821908 | H5: ='P&L WACD'!AS6 -> 0.080140305 | I5: ='P&L WACD'!AT6 -> 0.086795626 | J5: ='P&L WACD'!AU6 -> 0.093264005 | K5: ='P&L WACD'!AV6 -> 0.088356974 | ... O5: ='P&L WACD'!AZ6 -> 0.092860354 | P5: =SUM(D5:O5) -> 1 | S5: Revenue | T5: 3805685 | U5: 4754476.6 | V5: =-SUM('P&L WACD'!AC19:AN19) -> 5896558.4 | W5: =-SUM('P&L WACD'!AO19:AZ19) -> 7036925.6 | X5: =X6+W5 -> 7786925.6
C6: Average | D6: =AVERAGE(D4:D5) -> 0.075299696 | E6: =AVERAGE(E4:E5) -> 0.079272347 | F6: =AVERAGE(F4:F5) -> 0.078937941 | G6: =AVERAGE(G4:G5) -> 0.077998344 | H6: =AVERAGE(H4:H5) -> 0.080277554 | I6: =AVERAGE(I4:I5) -> 0.084365937 | J6: =AVERAGE(J4:J5) -> 0.089022037 | K6: =AVERAGE(K4:K5) -> 0.087577291 | ... O6: =AVERAGE(O4:O5) -> 0.090411913 | P6: =SUM(D6:O6) -> 1 | S6: Revenue growth abs. | U6: =U5-T5 -> 948791.61 | V6: =V5-U5 -> 1142081.8 | W6: =W5-V5 -> 1140367.1 | X6: 750000
S7: Revenue growth % | U7: =U5/T5-1 -> 0.24930902 | V7: =V5/U5-1 -> 0.2402119 | W7: =W5/V5-1 -> 0.19339537 | X7: =X5/W5-1 -> 0.10658064
B8: Budget | C8: FY 26/27 | D8: =$X$5*D6 -> 586353.13 | E8: =$X$5*E6 -> 617287.87 | F8: =$X$5*F6 -> 614683.87 | G8: =$X$5*G6 -> 607367.3 | H8: =$X$5*H6 -> 625115.34 | I8: =$X$5*I6 -> 656951.28 | J8: =$X$5*J6 -> 693207.97 | K8: =$X$5*K6 -> 681957.85 | ... O8: =$X$5*O6 -> 704030.84 | P8: =SUM(D8:O8) -> 7786925.6
B9: Actual | C9: FY 26/27 | D9: =-'P&L WACD'!BA19 -> 617842.09 | E9: =-'P&L WACD'!BB19 -> 649472.9 | F9: =-'P&L WACD'!BC19 -> 679312.86 | G9: =-'P&L WACD'!BD19 -> 629471.91 | H9: =-'P&L WACD'!BE19 -> 640793.23 | S9: Cost | T9: =T5-T11 -> 1490020.5 | U9: =U5-U11 -> 2021831.4 | V9: =V5-V11 -> 3069366.6 | W9: =W5-W11 -> 3579540.5 | X9: =X5-X11 -> 4282809.1
B10: Actual vs Budget % | D10: =D9/D8-1 -> 0.053703073 | E10: =E9/E8-1 -> 0.052139424 | F10: =F9/F8-1 -> 0.10514183 | G10: =G9/G8-1 -> 0.036394134 | H10: =H9/H8-1 -> 0.025079995
B11: Actual vs Budget % - Ytd | E11: =SUM(D9:E9)/SUM(D8:E8)-1 -> 0.052901155 | F11: =SUM(E9:F9)/SUM(E8:F8)-1 -> 0.078584614 | G11: =SUM(F9:G9)/SUM(F8:G8)-1 -> 0.070973785 | H11: =SUM(G9:H9)/SUM(G8:H8)-1 -> 0.030655601 | S11: EBIT | T11: 2315664.5 | U11: =SUM('P&L WACD'!Q105:AB105) -> 2732645.2 | V11: =SUM('P&L WACD'!AC105:AN105) -> 2827191.8 | W11: =SUM('P&L WACD'!AO105:AZ105) -> 3457385 | X11: =+X5*X15 -> 3504116.5
B12: Actual YoY % - Ytd | E12: =SUM(D9:E9)/SUM('P&L WACD'!AO19:AP19)*-1-1 -> 0.17399731 | F12: =SUM(E9:F9)/SUM('P&L WACD'!AP19:AQ19)*-1-1 -> 0.21311464 | G12: =SUM(F9:G9)/SUM('P&L WACD'!AQ19:AR19)*-1-1 -> 0.22361246 | H12: =SUM(G9:H9)/SUM('P&L WACD'!AR19:AS19)*-1-1 -> 0.17245796 | S12: EBIT growth abs | U12: =U11-T11 -> 416980.73 | V12: =V11-U11 -> 94546.6 | W12: =W11-V11 -> 630193.2 | X12: =X11-W11 -> 46731.486
A13: 2 | B13: Cost | D13: Apr | E13: May | F13: Jun | G13: Jul | H13: Aug | I13: Sept | J13: Oct | K13: Nov | L13: Dec | M13: Jan | N13: Feb | O13: Mar | P13: Total | S13: EBIT growth % | U13: =U11/T11-1 -> 0.18006958 | V13: =V11/U11-1 -> 0.03459893 | W13: =W11/V11-1 -> 0.2229043 | X13: =X11/W11-1 -> 0.013516425
B14: Actual | C14: FY 24/25 | D14: ='P&L WACD'!AC108 -> 0.067360135 | E14: ='P&L WACD'!AD108 -> 0.062651167 | F14: ='P&L WACD'!AE108 -> 0.080061071 | G14: ='P&L WACD'!AF108 -> 0.089004864 | H14: ='P&L WACD'!AG108 -> 0.10320827 | I14: ='P&L WACD'!AH108 -> 0.07738101 | J14: ='P&L WACD'!AI108 -> 0.099789985 | K14: ='P&L WACD'!AJ108 -> 0.085365895 | ... O14: ='P&L WACD'!AN108 -> 0.083655924 | P14: =SUM(D14:O14) -> 1
B15: Actual | C15: FY 25/26 | D15: ='P&L WACD'!AO108 -> 0.062464469 | E15: ='P&L WACD'!AP108 -> 0.069652257 | F15: ='P&L WACD'!AQ108 -> 0.1274614 | G15: ='P&L WACD'!AR108 -> 0.068272835 | H15: ='P&L WACD'!AS108 -> 0.070301263 | I15: ='P&L WACD'!AT108 -> 0.090839801 | J15: ='P&L WACD'!AU108 -> 0.071909192 | K15: ='P&L WACD'!AV108 -> 0.081915829 | ... O15: ='P&L WACD'!AZ108 -> 0.091460922 | P15: =SUM(D15:O15) -> 1 | S15: EBIT as % of T/o | T15: =+T11/T5 -> 0.60847508 | U15: =+U11/U5 -> 0.57475206 | V15: =+V11/V5 -> 0.47946473 | W15: =+W11/W5 -> 0.49132039 | X15: 0.45
C16: Average | D16: =AVERAGE(D14:D15) -> 0.064912302 | E16: =AVERAGE(E14:E15) -> 0.066151712 | F16: =AVERAGE(F14:F15) -> 0.10376124 | G16: =AVERAGE(G14:G15) -> 0.07863885 | H16: =AVERAGE(H14:H15) -> 0.086754766 | I16: =AVERAGE(I14:I15) -> 0.084110405 | J16: =AVERAGE(J14:J15) -> 0.085849589 | K16: =AVERAGE(K14:K15) -> 0.083640862 | ... O16: =AVERAGE(O14:O15) -> 0.087558423 | P16: =SUM(D16:O16) -> 1
B18: Budget | C18: FY 26/27 | D18: =$X$9*D16 -> 278007 | E18: =$X$9*E16 -> 283315.15 | F18: =$X$9*F16 -> 444389.57 | G18: =$X$9*G16 -> 336795.18 | H18: =$X$9*H16 -> 371554.1 | I18: =$X$9*I16 -> 360228.81 | J18: =$X$9*J16 -> 367677.4 | K18: =$X$9*K16 -> 358217.84 | ... O18: =$X$9*O16 -> 374996.01 | P18: =SUM(D18:O18) -> 4282809.1
B19: Actual | C19: FY 26/27 | D19: ='P&L WACD'!AO107 -> 223594.1 | E19: ='P&L WACD'!AP107 -> 249323.08 | F19: ='P&L WACD'!AQ107 -> 456253.26 | G19: ='P&L WACD'!AR107 -> 244385.38 | H19: ='P&L WACD'!AS107 -> 251646.22
B20: Actual vs Budget % | D20: =D19/D18-1 -> -0.19572492 | E20: =E19/E18-1 -> -0.11997972 | F20: =F19/F18-1 -> 0.026696606 | G20: =G19/G18-1 -> -0.27437981 | H20: =H19/H18-1 -> -0.32271984
A23: 3 | B23: EBIT
B24: Budget | C24: FY 26/27 | D24: =D8-D18 -> 308346.13 | E24: =E8-E18 -> 333972.71 | F24: =F8-F18 -> 170294.3 | G24: =G8-G18 -> 270572.13 | H24: =H8-H18 -> 253561.24 | I24: =I8-I18 -> 296722.47 | J24: =J8-J18 -> 325530.58 | K24: =K8-K18 -> 323740.01 | ... O24: =O8-O18 -> 329034.83 | P24: =SUM(D24:O24) -> 3504116.5
B25: Actual | C25: FY 26/27 | D25: =D9-D19 -> 394247.99 | E25: =E9-E19 -> 400149.82 | F25: =F9-F19 -> 223059.6 | G25: =G9-G19 -> 385086.53 | H25: =H9-H19 -> 389147.01
B26: Actual vs Budget % | D26: =D25/D24-1 -> 0.27858907 | E26: =E25/E24-1 -> 0.19815124 | F26: =F25/F24-1 -> 0.30984769 | G26: =G25/G24-1 -> 0.42323061 | H26: =H25/H24-1 -> 0.53472593
A28: 4 | B28: EBIT Margin
B29: Budget | C29: FY 26/27 | D29: =D24/D8 -> 0.52587104 | E29: =E24/E8 -> 0.54103236 | F29: =F24/F8 -> 0.27704372 | G29: =G24/G8 -> 0.44548352 | H29: =H24/H8 -> 0.40562313
B30: Actual | C30: FY 26/27 | D30: =D25/D9 -> 0.63810478 | E30: =E25/E9 -> 0.61611473 | F30: =F25/F9 -> 0.32836063 | G30: =G25/G9 -> 0.61176126 | H30: =H25/H9 -> 0.60728952

Sheet Budget - Ken
B3: Revenue | D3: Apr | E3: May | F3: Jun | G3: Jul | H3: Aug | I3: Sep | J3: Oct | K3: Nov | L3: Dec | M3: Jan | N3: Feb | O3: Mar | P3: Total | T3: Actual | U3: Actual | V3: Estimate | W3: Budget | X3: Budget
B4: Actual | C4: FY 24/25 | D4: 0.074676379 | E4: 0.081064474 | F4: 0.079698561 | G4: 0.082174781 | H4: 0.080414804 | I4: 0.081936249 | J4: 0.084780069 | K4: 0.086797608 | L4: 0.089111249 | M4: 0.090038509 | N4: 0.081343846 | O4: 0.087963471 | P4: =SUM(D4:O4) -> 1 | T4: FY 23/24 | U4: FY 24/25 | V4: FY 25/26 | W4: FY 26/27 | X4: FY 25/26
B5: Actual | C5: FY 25/26 | D5: 0.076332074 | E5: 0.077897671 | F5: 0.078598529 | G5: 0.074219649 | H5: 0.080572089 | I5: 0.087263268 | J5: 0.093766497 | K5: 0.088833028 | L5: 0.091821726 | M5: 0.081444078 | N5: 0.081278568 | O5: 0.087972824 | P5: =SUM(D5:O5) -> 1 | S5: Revenue | T5: 4754476.6 | U5: 5896558.4 | V5: 6999214.9 | W5: 7749214.9 | X5: 6546558.4
C6: Average | D6: =(D4+D5)/2 -> 0.075504226 | E6: =(E4+E5)/2 -> 0.079481073 | F6: =(F4+F5)/2 -> 0.079148545 | G6: =(G4+G5)/2 -> 0.078197215 | H6: =(H4+H5)/2 -> 0.080493446 | I6: =(I4+I5)/2 -> 0.084599758 | J6: =(J4+J5)/2 -> 0.089273283 | K6: =(K4+K5)/2 -> 0.087815318 | ... O6: =(O4+O5)/2 -> 0.087968148 | P6: =SUM(D6:O6) -> 1 | S6: Revenue growth abs. | U6: =U5-T5 -> 1142081.8 | V6: =V5-U5 -> 1102656.4 | W6: =W5-V5 -> 750000
S7: Revenue growth % | U7: =U6/T5 -> 0.2402119 | V7: =V6/U5 -> 0.187 | W7: =W6/V5 -> 0.10715488
B8: Budget | C8: FY 26/27 | D8: =D6*P8 -> 585098.47 | E8: =E6*P8 -> 615915.91 | F8: =F6*P8 -> 613339.08 | G8: =G6*P8 -> 605967.02 | H8: =H6*P8 -> 623761.01 | I8: =I6*P8 -> 655581.7 | J8: =J6*P8 -> 691797.85 | K8: =K6*P8 -> 680499.77 | L8: =L6*P8 -> 701044.25 | M8: =M6*P8 -> 664427.71 | N8: =N6*P8 -> 630098.01 | O8: =O6*P8 -> 681684.08 | P8: 7749214.9
S9: Cost | T9: 2021831.4 | U9: 3069366.6 | V9: 3562600.4 | W9: 4262068.2 | X9: 3969366.6
S11: EBIT | T11: 2732645.2 | U11: 2827191.8 | V11: 3436614.5 | W11: 3487146.7 | X11: 2577191.8
S12: EBIT growth abs | U12: =U11-T11 -> 94546.6 | V12: =V11-U11 -> 609422.68
B13: Cost | D13: Apr | E13: May | F13: Jun | G13: Jul | H13: Aug | I13: Sep | J13: Oct | K13: Nov | L13: Dec | M13: Jan | N13: Feb | O13: Mar | P13: Total | S13: EBIT growth % | U13: =U12/T11 -> 0.03459893 | V13: =V12/U11 -> 0.2155576
B14: Actual | C14: FY 24/25 | D14: 0.067360135 | E14: 0.062651167 | F14: 0.080061071 | G14: 0.089004864 | H14: 0.10320827 | I14: 0.07738101 | J14: 0.099789985 | K14: 0.085365895 | L14: 0.083821557 | M14: 0.091358969 | N14: 0.076341151 | O14: 0.083655924 | P14: =SUM(D14:O14) -> 1
B15: Actual | C15: FY 25/26 | D15: 0.062761488 | E15: 0.069983454 | F15: 0.12806748 | G15: 0.068597472 | H15: 0.070635545 | I15: 0.091271744 | J15: 0.072251121 | K15: 0.082305339 | L15: 0.092511215 | M15: 0.091884771 | N15: 0.082385522 | O15: 0.087344845 | P15: =SUM(D15:O15) -> 1 | S15: EBIT margin | T15: =T11/T5 -> 0.57475206 | U15: =U11/U5 -> 0.47946473 | V15: =V11/V5 -> 0.491 | W15: =W11/W5 -> 0.45
C16: Average | D16: =(D14+D15)/2 -> 0.065060811 | E16: =(E14+E15)/2 -> 0.066317311 | F16: =(F14+F15)/2 -> 0.10406428 | G16: =(G14+G15)/2 -> 0.078801168 | H16: =(H14+H15)/2 -> 0.086921908 | I16: =(I14+I15)/2 -> 0.084326377 | J16: =(J14+J15)/2 -> 0.086020553 | K16: =(K14+K15)/2 -> 0.083835617 | ... O16: =(O14+O15)/2 -> 0.085500385 | P16: =SUM(D16:O16) -> 1
B18: Budget | C18: FY 26/27 | D18: =D16*P18 -> 277293.61 | E18: =E16*P18 -> 282648.9 | F18: =F16*P18 -> 443529.04 | G18: =G16*P18 -> 335855.95 | H18: =H16*P18 -> 370467.1 | I18: =I16*P18 -> 359404.77 | J18: =J16*P18 -> 366625.46 | K18: =K16*P18 -> 357313.12 | L18: =L16*P18 -> 375771.15 | M18: =M16*P18 -> 390498.66 | N18: =N16*P18 -> 338251.95 | O18: =O16*P18 -> 364408.47 | P18: 4262068.2
B23: EBIT | D23: Apr | E23: May | F23: Jun | G23: Jul | H23: Aug | I23: Sep | J23: Oct | K23: Nov | L23: Dec | M23: Jan | N23: Feb | O23: Mar | P23: Total
B24: Budget | C24: FY 26/27 | D24: =D8-D18 -> 307804.86 | E24: =E8-E18 -> 333267.01 | F24: =F8-F18 -> 169810.04 | G24: =G8-G18 -> 270111.07 | H24: =H8-H18 -> 253293.91 | I24: =I8-I18 -> 296176.94 | J24: =J8-J18 -> 325172.39 | K24: =K8-K18 -> 323186.65 | ... O24: =O8-O18 -> 317275.61 | P24: =SUM(D24:O24) -> 3487146.7
B28: EBIT Margin
B29: Budget | C29: FY 26/27 | D29: =D24/D8 -> 0.5260736 | E29: =E24/E8 -> 0.54109174 | F29: =F24/F8 -> 0.2768616 | G29: =G24/G8 -> 0.4457521 | H29: =H24/H8 -> 0.40607526 | I29: =I24/I8 -> 0.4517773 | J29: =J24/J8 -> 0.47003961 | K29: =K24/K8 -> 0.47492544 | ... P29: =P24/P8 -> 0.45

Sheet Budget - Int & Taxes
A1: Row Labels | B1: Sum of 20244 | C1: Sum of 20245 | D1: Sum of 20246 | E1: Sum of 20247 | F1: Sum of 20248 | G1: Sum of 20249 | H1: Sum of 202410 | I1: Sum of 202411 | J1: Sum of 202412 | K1: Sum of 2025 | L1: Sum of 20252 | M1: Sum of 20253 | N1: Total | O1: % | P1: T/o | Q1: Monthly Avg
A2: Interest | B2: -10870.46 | C2: -13882.26 | D2: -14642.42 | E2: -11364.33 | F2: -11127.95 | G2: -13811.4 | H2: -24145.32 | I2: -24963.52 | J2: -24665.9 | K2: -26513.59 | L2: -17470.32 | M2: -13233.52 | N2: =SUM(B2:M2) -> -206690.99 | Q2: =+N2/12 -> -17224.249
A3: Taxes | B3: 43114.36 | C3: 55839.87 | D3: 42829.52 | E3: 32034.45 | F3: 80242.11 | G3: 86706 | H3: 75262.12 | I3: 66265 | J3: 63229 | K3: 71734.72 | L3: 54664 | M3: 87840 | N3: =SUM(B3:M3) -> 759761.15 | O3: =+N3/P3 -> 0.12884824 | P3: 5896558.4
A4: Grand Total | B4: 32243.9 | C4: 41957.61 | D4: 28187.1 | E4: 20670.12 | F4: 69114.16 | G4: 72894.6 | H4: 51116.8 | I4: 41301.48 | J4: 38563.1 | K4: 45221.13 | L4: 37193.68 | M4: 74606.48 | N4: =SUM(B4:M4) -> 553070.16
N5: =SUM(N2:N4) -> 1106140.3
A7: Row Labels | B7: Sum of 20254 | C7: Sum of 20255 | D7: Sum of 20256 | E7: Sum of 20257 | F7: Sum of 20258 | G7: Sum of 20259 | H7: Sum of 202510 | I7: Sum of 202511 | J7: Sum of 202512 | K7: Sum of 2026 | L7: Sum of 20262 | M7: Sum of 20263
A8: Interest | B8: -802.33 | C8: -19684.85 | D8: -12127.02 | E8: -27461.62 | F8: -15566.35 | G8: -36819.38 | H8: -10191.35 | I8: -21404.73 | J8: -18127.65 | K8: -19121.79 | L8: -27033.99 | M8: -35258.03 | N8: =SUM(B8:M8) -> -243599.09 | Q8: =+N8/12 -> -20299.924
A9: Taxes | B9: 68950 | C9: 81605 | D9: 26394 | E9: 78720 | F9: 85833 | G9: 78748.41 | H9: 107561.76 | I9: 88185.99 | J9: 86825.82 | K9: 67432.36 | L9: 78280 | M9: 93100 | N9: =SUM(B9:M9) -> 941636.34 | O9: =+N9/P9 -> 0.1338136 | P9: 7036925.6
A10: Grand Total | B10: 68147.67 | C10: 61920.15 | D10: 14266.98 | E10: 51258.38 | F10: 70266.65 | G10: 41929.03 | H10: 97370.41 | I10: 66781.26 | J10: 68698.17 | K10: 48310.57 | L10: 51246.01 | M10: 57841.97 | N10: =SUM(B10:M10) -> 698037.25
N11: =SUM(N8:N10) -> 1396074.5
Q12: =+AVERAGE(Q8,Q2) -> -18762.087
O14: Tax is budgeted @ 13%

Sheet Budget - Cost
A1: Row Labels | B1: Sum of 20244 | C1: Sum of 20245 | D1: Sum of 20246 | E1: Sum of 20247 | F1: Sum of 20248 | G1: Sum of 20249 | H1: Sum of 202410 | I1: Sum of 202411 | J1: Sum of 202412 | K1: Sum of 2025 | L1: Sum of 20252 | M1: Sum of 20253
A2: COGS | B2: 7155.9 | C2: 6655.11 | D2: 36583.34 | E2: 25780.1 | F2: 5822.75 | G2: 6136.45 | H2: 55014.13 | I2: 1860.7 | J2: 1929.01 | K2: 1934.88 | L2: 2029.5 | M2: 1801.75 | N2: =SUM(B2:M2) -> 152703.62
A3: General | B3: 62587.98 | C3: 61042.19 | D3: 68117.71 | E3: 98716.81 | F3: 72232.84 | G3: 78966.48 | H3: 93031.85 | I3: 110141.24 | J3: 104418.4 | K3: 118511.42 | L3: 76889.94 | M3: 91340.87 | N3: =SUM(B3:M3) -> 1035997.7
A4: Personnel | B4: 137009.07 | C4: 124602.1 | D4: 141035.73 | E4: 148691.65 | F4: 238728.43 | G4: 152407.76 | H4: 158246.07 | I4: 150017.29 | J4: 150931.68 | K4: 159967.87 | L4: 155399.54 | M4: 163628.08 | N4: =SUM(B4:M4) -> 1880665.3
A5: Grand Total | B5: 206752.95 | C5: 192299.4 | D5: 245736.78 | E5: 273188.56 | F5: 316784.02 | G5: 237510.69 | H5: 306292.05 | I5: 262019.23 | J5: 257279.09 | K5: 280414.17 | L5: 234318.98 | M5: 256770.7 | N5: =SUM(N2:N4) -> 3069366.6
A7: FY 24/25
A8: COGS | B8: =+B2/B$5 -> 0.034610873 | C8: =+C2/C$5 -> 0.034608064 | D8: =+D2/D$5 -> 0.14887206 | E8: =+E2/E$5 -> 0.094367422 | F8: =+F2/F$5 -> 0.01838082 | G8: =+G2/G$5 -> 0.025836521 | H8: =+H2/H$5 -> 0.17961331 | I8: =+I2/I$5 -> 0.0071013872 | ... N8: =+N2/N$5 -> 0.049750857
A9: General | B9: =+B3/B$5 -> 0.30271868 | C9: =+C3/C$5 -> 0.31743308 | D9: =+D3/D$5 -> 0.27719786 | E9: =+E3/E$5 -> 0.36135045 | F9: =+F3/F$5 -> 0.2280192 | G9: =+G3/G$5 -> 0.33247548 | H9: =+H3/H$5 -> 0.30373576 | I9: =+I3/I$5 -> 0.42035556 | ... N9: =+N3/N$5 -> 0.33752818
A10: Personnel | B10: =+B4/B$5 -> 0.66267045 | C10: =+C4/C$5 -> 0.64795886 | D10: =+D4/D$5 -> 0.57393008 | E10: =+E4/E$5 -> 0.54428213 | F10: =+F4/F$5 -> 0.75359998 | G10: =+G4/G$5 -> 0.641688 | H10: =+H4/H$5 -> 0.51665092 | I10: =+I4/I$5 -> 0.57254305 | ... N10: =+N4/N$5 -> 0.61272096
A13: Row Labels | B13: Sum of 20254 | C13: Sum of 20255 | D13: Sum of 20256 | E13: Sum of 20257 | F13: Sum of 20258 | G13: Sum of 20259 | H13: Sum of 202510 | I13: Sum of 202511 | J13: Sum of 202512 | K13: Sum of 2026 | L13: Sum of 20262 | M13: Sum of 20263
A14: COGS | B14: 539.19 | C14: 486.38 | D14: 805.44 | E14: 2615.38 | F14: 2744.64 | G14: 2810.74 | H14: 4828.72 | I14: 6554.09 | J14: 6772.57 | K14: 32072.6 | L14: 16499.66 | M14: 14980 | N14: =SUM(B14:M14) -> 91709.41
A15: General | B15: 69899.22 | C15: 91831.74 | D15: 111934.19 | E15: 76457.8 | F15: 60816.31 | G15: 113547.76 | H15: 81857.59 | I15: 91656.97 | J15: 102076.79 | K15: 103154.28 | L15: 97629.09 | M15: 111107.66 | N15: =SUM(B15:M15) -> 1111969.4
A16: Personnel | B16: 153155.69 | C16: 157004.96 | D16: 343513.63 | E16: 165312.2 | F16: 188085.27 | G16: 208806.25 | H16: 170715.56 | I16: 195009.97 | J16: 220731.13 | K16: 192121.84 | L16: 180104.82 | M16: 201300.42 | N16: =SUM(B16:M16) -> 2375861.7
A17: Grand Total | B17: 223594.1 | C17: 249323.08 | D17: 456253.26 | E17: 244385.38 | F17: 251646.22 | G17: 325164.75 | H17: 257401.87 | I17: 293221.03 | J17: 329580.49 | K17: 327348.72 | L17: 294233.57 | M17: 327388.08 | N17: =SUM(N14:N16) -> 3579540.5
A19: FY 25/26
A20: COGS | B20: =+B14/B$17 -> 0.0024114679 | C20: =+C14/C$17 -> 0.0019508021 | D20: =+D14/D$17 -> 0.0017653353 | E20: =+E14/E$17 -> 0.010701868 | F20: =+F14/F$17 -> 0.01090674 | G20: =+G14/G$17 -> 0.0086440489 | H20: =+H14/H$17 -> 0.01875946 | I20: =+I14/I$17 -> 0.022352046 | ... N20: =+N14/N$17 -> 0.025620442
A21: General | B21: =+B15/B$17 -> 0.31261657 | C21: =+C15/C$17 -> 0.36832426 | D21: =+D15/D$17 -> 0.24533346 | E21: =+E15/E$17 -> 0.3128575 | F21: =+F15/F$17 -> 0.24167385 | G21: =+G15/G$17 -> 0.34920071 | H21: =+H15/H$17 -> 0.31801474 | I21: =+I15/I$17 -> 0.31258662 | ... N21: =+N15/N$17 -> 0.31064585
A22: Personnel | B22: =+B16/B$17 -> 0.68497196 | C22: =+C16/C$17 -> 0.62972493 | D22: =+D16/D$17 -> 0.75290121 | E22: =+E16/E$17 -> 0.67644063 | F22: =+F16/F$17 -> 0.74741941 | G22: =+G16/G$17 -> 0.64215525 | H22: =+H16/H$17 -> 0.6632258 | I22: =+I16/I$17 -> 0.66506134 | ... N22: =+N16/N$17 -> 0.66373371
A24: FY 26/27
A25: COGS | B25: =+AVERAGE(B20,B8) -> 0.01851117 | C25: =+AVERAGE(C20,C8) -> 0.018279433 | D25: =+AVERAGE(D20,D8) -> 0.075318696 | E25: =+AVERAGE(E20,E8) -> 0.052534645 | F25: =+AVERAGE(F20,F8) -> 0.01464378 | G25: =+AVERAGE(G20,G8) -> 0.017240285 | H25: =+AVERAGE(H20,H8) -> 0.099186387 | I25: =+AVERAGE(I20,I8) -> 0.014726717 | ... N25: =+AVERAGE(N20,N8) -> 0.037685649
A26: General | B26: =+AVERAGE(B21,B9) -> 0.30766762 | C26: =+AVERAGE(C21,C9) -> 0.34287867 | D26: =+AVERAGE(D21,D9) -> 0.26126566 | E26: =+AVERAGE(E21,E9) -> 0.33710398 | F26: =+AVERAGE(F21,F9) -> 0.23484653 | G26: =+AVERAGE(G21,G9) -> 0.34083809 | H26: =+AVERAGE(H21,H9) -> 0.31087525 | I26: =+AVERAGE(I21,I9) -> 0.36647109 | ... N26: =+AVERAGE(N21,N9) -> 0.32408701
A27: Personnel | B27: =+AVERAGE(B22,B10) -> 0.67382121 | C27: =+AVERAGE(C22,C10) -> 0.6388419 | D27: =+AVERAGE(D22,D10) -> 0.66341564 | E27: =+AVERAGE(E22,E10) -> 0.61036138 | F27: =+AVERAGE(F22,F10) -> 0.75050969 | G27: =+AVERAGE(G22,G10) -> 0.64192162 | H27: =+AVERAGE(H22,H10) -> 0.58993836 | I27: =+AVERAGE(I22,I10) -> 0.61880219 | ... N27: =+AVERAGE(N22,N10) -> 0.63822734
A30: Budgeted Costs FY 26/27 | B30: =+'Budget - Overview'!D18 -> 278007 | C30: =+'Budget - Overview'!E18 -> 283315.15 | D30: =+'Budget - Overview'!F18 -> 444389.57 | E30: =+'Budget - Overview'!G18 -> 336795.18 | F30: =+'Budget - Overview'!H18 -> 371554.1 | G30: =+'Budget - Overview'!I18 -> 360228.81 | H30: =+'Budget - Overview'!J18 -> 367677.4 | I30: =+'Budget - Overview'!K18 -> 358217.84 | ... M30: =+'Budget - Overview'!O18 -> 374996.01 | N30: =SUM(B30:M30) -> 4282809.1
A32: FY 26/27
A33: COGS | B33: =+B$30*B25 -> 5146.2348 | C33: =+C$30*C25 -> 5178.8404 | D33: =+D$30*D25 -> 33470.843 | E33: =+E$30*E25 -> 17693.415 | F33: =+F$30*F25 -> 5440.9565 | G33: =+G$30*G25 -> 6210.4473 | H33: =+H$30*H25 -> 36468.592 | I33: =+I$30*I25 -> 5275.3727 | ... M33: =+M$30*M25 -> 9894.8426 | N33: =SUM(B33:M33) -> 161578.81
A34: General | B34: =+B$30*B26 -> 85533.752 | C34: =+C$30*C26 -> 97142.723 | D34: =+D$30*D26 -> 116103.73 | E34: =+E$30*E26 -> 113534.99 | F34: =+F$30*F26 -> 87258.189 | G34: =+G$30*G26 -> 122779.7 | H34: =+H$30*H26 -> 114301.8 | I34: =+I$30*I26 -> 131276.48 | ... M34: =+M$30*M26 -> 130330.86 | N34: =SUM(B34:M34) -> 1389455.7
A35: Personnel | B35: =+B$30*B27 -> 187327.01 | C35: =+C$30*C27 -> 180993.59 | D35: =+D$30*D27 -> 294814.99 | E35: =+E$30*E27 -> 205566.77 | F35: =+F$30*F27 -> 278854.95 | G35: =+G$30*G27 -> 231238.66 | H35: =+H$30*H27 -> 216907 | I35: =+I$30*I27 -> 221665.99 | ... M35: =+M$30*M27 -> 234770.3 | N35: =SUM(B35:M35) -> 2731774.5
